Workbook

Sheet Income Statement
C1: Ticker Name: | D1: tsla
C3: Current Price | D3: =IFERROR(__xludf.DUMMYFUNCTION("GOOGLEFINANCE(D1,""PRICE"")"),393.45) -> 393.45 | E3: %-change from implied | F3: =D4/D3-1 -> -0.65042537
C4: Implied Share Value | D4: =DCF!C85 -> 137.54014 | E4: %-change (1 month) | F4: =IFERROR(__xludf.DUMMYFUNCTION("(D3-INDEX(GOOGLEFINANCE(D1,""price"",EDATE(TODAY(),-1)),2,2))/D3"),-0.0768839750921337) -> -0.076883975
C6: Chart (1 years) | D6: =IFERROR(__xludf.DUMMYFUNCTION("SPARKLINE(INDEX(GOOGLEFINANCE(D1,""price"",EDATE(today(),-12),today()), ,2),{""charttype"",""column"";""color"",""red""})"),"") | E6: %-change (6 months) | F6: =IFERROR(__xludf.DUMMYFUNCTION("(D3-INDEX(GOOGLEFINANCE(D1,""price"",EDATE(TODAY(),-6)),2,2))/D3"),-0.1479730588384802) -> -0.14797306
C8: Chart (5 years) | D8: =IFERROR(__xludf.DUMMYFUNCTION("SPARKLINE(INDEX(GOOGLEFINANCE(D1,""price"",EDATE(today(),-60),today()), ,2),{""charttype"",""column"";""color"",""red""})"),"") | E8: %-change (12 months) | F8: =IFERROR(__xludf.DUMMYFUNCTION("(D3-INDEX(GOOGLEFINANCE(D1,""price"",EDATE(TODAY(),-12)),2,2))/D3"),0.1985004447833269) -> 0.19850044
B11: Income Statement | C11: FY | H11: Future FY
C12: 2021 | D12: =C12+1 -> 2022 | E12: =D12+1 -> 2023 | F12: =E12+1 -> 2024 | G12: =F12+1 -> 2025 | H12: =G12+1 -> 2026 | I12: =H12+1 -> 2027 | J12: =I12+1 -> 2028 | K12: =J12+1 -> 2029 | L12: =K12+1 -> 2030
B15: Revenue | C15: =IFERROR(__xludf.DUMMYFUNCTION("IFERROR( LET( x, UPPER(SUBSTITUTE(TRIM(Data!B5),CHAR(160),"""")), base, VALUE(SUBSTITUTE(REGEXEXTRACT(x,""[0-9.,]+""),"","","""")), mult, IF(REGEXMATCH(x,""B""),1000000000, IF(REGEXMATCH(x,""M""),1000000, 1)), base * mult ), 0 )"),5.382E10) -> 53820000000 | D15: =IFERROR(__xludf.DUMMYFUNCTION("IFERROR( LET( x, UPPER(SUBSTITUTE(TRIM(Data!C5),CHAR(160),"""")), base, VALUE(SUBSTITUTE(REGEXEXTRACT(x,""[0-9.,]+""),"","","""")), mult, IF(REGEXMATCH(x,""B""),1000000000, IF(REGEXMATCH(x,""M""),1000000, 1)), base * mult ), 0 )"),8.146E10) -> 81460000000 | E15: =IFERROR(__xludf.DUMMYFUNCTION("IFERROR( LET( x, UPPER(SUBSTITUTE(TRIM(Data!D5),CHAR(160),"""")), base, VALUE(SUBSTITUTE(REGEXEXTRACT(x,""[0-9.,]+""),"","","""")), mult, IF(REGEXMATCH(x,""B""),1000000000, IF(REGEXMATCH(x,""M""),1000000, 1)), base * mult ), 0 )"),9.677E10) -> 96770000000 | F15: =IFERROR(__xludf.DUMMYFUNCTION("IFERROR( LET( x, UPPER(SUBSTITUTE(TRIM(Data!E5),CHAR(160),"""")), base, VALUE(SUBSTITUTE(REGEXEXTRACT(x,""[0-9.,]+""),"","","""")), mult, IF(REGEXMATCH(x,""B""),1000000000, IF(REGEXMATCH(x,""M""),1000000, 1)), base * mult ), 0 )"),9.769E10) -> 97690000000 | G15: =IFERROR(__xludf.DUMMYFUNCTION("IFERROR( LET( x, UPPER(SUBSTITUTE(TRIM(Data!F5),CHAR(160),"""")), base, VALUE(SUBSTITUTE(REGEXEXTRACT(x,""[0-9.,]+""),"","","""")), mult, IF(REGEXMATCH(x,""B""),1000000000, IF(REGEXMATCH(x,""M""),1000000, 1)), base * mult ), 0 )"),9.483E10) -> 94830000000 | H15: =DCF!H8 -> 102430000000 | I15: =H15*(1+H16) -> 118012412056 | J15: =I15*(1+I16) -> 135965336320 | K15: =J15*(1+J16) -> 156649392708 | L15: =K15*(1+K16) -> 180480061315
B16: Revenue Growth | C16: =Data!B6 -> - | D16: =Data!C6 -> 0.5135 | E16: =Data!D6 -> 0.188 | F16: =Data!E6 -> 0.0095 | G16: =Data!F6 -> -0.0293 | H16: =(G15/C15)^(1/4)-1 -> 0.15212742 | I16: =H16 -> 0.15212742 | J16: =I16 -> 0.15212742 | K16: =J16 -> 0.15212742 | L16: =K16 -> 0.15212742
B18: Cost of Sales | C18: =Data!B7 -> 40.22B | D18: =Data!C7 -> 60.61B | E18: =Data!D7 -> 79.11B | F18: =Data!E7 -> 80.24B | G18: =Data!F7 -> 77.73B | H18: =H15-H19 -> 84338980277 | I18: =I15-I19 -> 98861739463 | J18: =J15-J19 -> 115692943366 | K18: =K15-K19 -> 135189576396 | L18: =L15-L19 -> 157763270201
B19: Gross Profit | C19: =Data!B13 -> 13.61B | D19: =Data!C13 -> 20.85B | E19: =Data!D13 -> 17.66B | F19: =Data!E13 -> 17.45B | G19: =Data!F13 -> 17.09B | H19: =IFERROR(__xludf.DUMMYFUNCTION("REGEXREPLACE(G19,""B"","""")*1000000000*(1+H20)"),1.809101972289867E10) -> 18091019723 | I19: =H19*(1+I20) -> 19150672593 | J19: =I19*(1+J20) -> 20272392954 | K19: =J19*(1+K20) -> 21459816312 | L19: =K19*(1+L20) -> 22716791114
B20: Gross Profit Growth | C20: =Data!B14 -> - | D20: =Data!C14 -> 0.5326 | E20: =Data!D14 -> -0.1531 | F20: =Data!E14 -> -0.0119 | G20: =Data!F14 -> -0.0204 | H20: =IFERROR(__xludf.DUMMYFUNCTION("(REGEXREPLACE(G19,""B"","""")/REGEXREPLACE(C19,""B"",""""))^(1/4)-1"),0.058573418542929856) -> 0.058573419 | I20: =H20 -> 0.058573419 | J20: =I20 -> 0.058573419 | K20: =J20 -> 0.058573419 | L20: =K20 -> 0.058573419
B23: Selling, General & Admin | C23: =IFERROR(__xludf.DUMMYFUNCTION("IFERROR( LET( x, UPPER(SUBSTITUTE(TRIM(Data!B16),CHAR(160),"""")), base, VALUE(SUBSTITUTE(REGEXEXTRACT(x,""[0-9.,]+""),"","","""")), mult, IF(REGEXMATCH(x,""B""),1000000000, IF(REGEXMATCH(x,""M""),1000000, 1)), base * mult ), 0 )"),7.11E9) -> 7110000000 | D23: =IFERROR(__xludf.DUMMYFUNCTION("IFERROR( LET( x, UPPER(SUBSTITUTE(TRIM(Data!C16),CHAR(160),"""")), base, VALUE(SUBSTITUTE(REGEXEXTRACT(x,""[0-9.,]+""),"","","""")), mult, IF(REGEXMATCH(x,""B""),1000000000, IF(REGEXMATCH(x,""M""),1000000, 1)), base * mult ), 0 )"),7.02E9) -> 7020000000 | E23: =IFERROR(__xludf.DUMMYFUNCTION("IFERROR( LET( x, UPPER(SUBSTITUTE(TRIM(Data!D16),CHAR(160),"""")), base, VALUE(SUBSTITUTE(REGEXEXTRACT(x,""[0-9.,]+""),"","","""")), mult, IF(REGEXMATCH(x,""B""),1000000000, IF(REGEXMATCH(x,""M""),1000000, 1)), base * mult ), 0 )"),8.77E9) -> 8770000000 | F23: =IFERROR(__xludf.DUMMYFUNCTION("IFERROR( LET( x, UPPER(SUBSTITUTE(TRIM(Data!E16),CHAR(160),"""")), base, VALUE(SUBSTITUTE(REGEXEXTRACT(x,""[0-9.,]+""),"","","""")), mult, IF(REGEXMATCH(x,""B""),1000000000, IF(REGEXMATCH(x,""M""),1000000, 1)), base * mult ), 0 )"),9.69E9) -> 9690000000 | G23: =IFERROR(__xludf.DUMMYFUNCTION("IFERROR( LET( x, UPPER(SUBSTITUTE(TRIM(Data!F16),CHAR(160),"""")), base, VALUE(SUBSTITUTE(REGEXEXTRACT(x,""[0-9.,]+""),"","","""")), mult, IF(REGEXMATCH(x,""B""),1000000000, IF(REGEXMATCH(x,""M""),1000000, 1)), base * mult ), 0 )"),1.225E10) -> 12250000000 | H23: - | I23: - | J23: - | K23: - | L23: -
B24: Depreciation & Amortization Expense | C24: =Data!B10 -> 2.91B | D24: =Data!C10 -> 3.54B | E24: =Data!D10 -> 4.67B | F24: =Data!E10 -> 5.37B | G24: =Data!F10 -> 6.15B | H24: - | I24: - | J24: - | K24: - | L24: -
B25: Unusual Expense | C25: =Data!B21 -> (40M) | D25: =Data!C21 -> 150M | E25: =Data!D21 -> 4M | F25: =Data!E21 -> 670M | G25: =Data!F21 -> 562M | H25: - | I25: - | J25: - | K25: - | L25: -
B26: Operating Expenses | C26: =C23 -> 7110000000 | D26: =D23 -> 7020000000 | E26: =E23 -> 8770000000 | F26: =F23 -> 9690000000 | G26: =G23 -> 12250000000 | H26: =G26*(1+H27) -> 14034686328 | I26: =H26*(1+I27) -> 16079381251 | J26: =I26*(1+J27) -> 18421965078 | K26: =J26*(1+K27) -> 21105836850 | L26: =K26*(1+L27) -> 24180718357
B27: Operating Expenses Growth | C27: - | D27: =D26/C26-1 -> -0.012658228 | E27: =E26/D26-1 -> 0.24928775 | F27: =F26/E26-1 -> 0.10490308 | G27: =G26/F26-1 -> 0.26418989 | H27: =(G26/C26)^(1/4)-1 -> 0.14568868 | I27: =H27 -> 0.14568868 | J27: =I27 -> 0.14568868 | K27: =J27 -> 0.14568868 | L27: =K27 -> 0.14568868
B28: Operating Income | C28: =IFERROR(__xludf.DUMMYFUNCTION("(REGEXREPLACE(C19,""B"","""")*1000000000)-C26"),6.5E9) -> 6500000000 | D28: =IFERROR(__xludf.DUMMYFUNCTION("(REGEXREPLACE(D19,""B"","""")*1000000000)-D26"),1.383E10) -> 13830000000 | E28: =IFERROR(__xludf.DUMMYFUNCTION("(REGEXREPLACE(E19,""B"","""")*1000000000)-E26"),8.89E9) -> 8890000000 | F28: =IFERROR(__xludf.DUMMYFUNCTION("(REGEXREPLACE(F19,""B"","""")*1000000000)-F26"),7.76E9) -> 7760000000 | G28: =IFERROR(__xludf.DUMMYFUNCTION("(REGEXREPLACE(G19,""B"","""")*1000000000)-G26"),4.84E9) -> 4840000000 | H28: =G28*(1+H29) -> 4496021329 | I28: =H28*(1+I29) -> 4221449427 | J28: =I28*(1+J29) -> 4005860118 | K28: =J28*(1+K29) -> 3841339550 | L28: =K28*(1+L29) -> 3721989233
B29: Operating Income Growth | C29: - | D29: =D28/C28-1 -> 1.1276923 | E29: =E28/D28-1 -> -0.3571945 | F29: =F28/E28-1 -> -0.12710911 | G29: =G28/F28-1 -> -0.37628866 | H29: =(G28/C28)^(1/4)-1 -> -0.071069973 | I29: =H29+1% -> -0.061069973 | J29: =I29+1% -> -0.051069973 | K29: =J29+1% -> -0.041069973 | L29: =K29+1% -> -0.031069973
B32: EBIT | C32: =Data!B22 -> 6.54B | D32: =Data!C22 -> 13.68B | E32: =Data!D22 -> 8.89B | F32: =Data!E22 -> 7.09B | G32: =Data!F22 -> 4.29B | H32: - | I32: - | J32: - | K32: - | L32: -
B33: EBITDA | C33: =IFERROR(__xludf.DUMMYFUNCTION("IFERROR( LET( x, UPPER(SUBSTITUTE(TRIM(Data!B59),CHAR(160),"""")), base, VALUE(SUBSTITUTE(REGEXEXTRACT(x,""[0-9.,]+""),"","","""")), mult, IF(REGEXMATCH(x,""B""),1000000000, IF(REGEXMATCH(x,""M""),1000000, 1)), base * mult ), 0 )"),9.41E9) -> 9410000000 | D33: =IFERROR(__xludf.DUMMYFUNCTION("IFERROR( LET( x, UPPER(SUBSTITUTE(TRIM(Data!C59),CHAR(160),"""")), base, VALUE(SUBSTITUTE(REGEXEXTRACT(x,""[0-9.,]+""),"","","""")), mult, IF(REGEXMATCH(x,""B""),1000000000, IF(REGEXMATCH(x,""M""),1000000, 1)), base * mult ), 0 )"),1.738E10) -> 17380000000 | E33: =IFERROR(__xludf.DUMMYFUNCTION("IFERROR( LET( x, UPPER(SUBSTITUTE(TRIM(Data!D59),CHAR(160),"""")), base, VALUE(SUBSTITUTE(REGEXEXTRACT(x,""[0-9.,]+""),"","","""")), mult, IF(REGEXMATCH(x,""B""),1000000000, IF(REGEXMATCH(x,""M""),1000000, 1)), base * mult ), 0 )"),1.356E10) -> 13560000000 | F33: =IFERROR(__xludf.DUMMYFUNCTION("IFERROR( LET( x, UPPER(SUBSTITUTE(TRIM(Data!E59),CHAR(160),"""")), base, VALUE(SUBSTITUTE(REGEXEXTRACT(x,""[0-9.,]+""),"","","""")), mult, IF(REGEXMATCH(x,""B""),1000000000, IF(REGEXMATCH(x,""M""),1000000, 1)), base * mult ), 0 )"),1.313E10) -> 13130000000 | G33: =IFERROR(__xludf.DUMMYFUNCTION("IFERROR( LET( x, UPPER(SUBSTITUTE(TRIM(Data!F59),CHAR(160),"""")), base, VALUE(SUBSTITUTE(REGEXEXTRACT(x,""[0-9.,]+""),"","","""")), mult, IF(REGEXMATCH(x,""B""),1000000000, IF(REGEXMATCH(x,""M""),1000000, 1)), base * mult ), 0 )"),1.1E10) -> 11000000000 | H33: =G33*(1+H34) -> 11437825081 | I33: =H33*(1+I34) -> 11893076599 | J33: =I33*(1+J34) -> 12366448165 | K33: =J33*(1+K34) -> 12858660999 | L33: =K33*(1+L34) -> 13370465026
B34: EBITDA Growth | C34: =Data!B60 -> - | D34: =Data!C60 -> 0.847 | E34: =Data!D60 -> -0.2197 | F34: =Data!E60 -> -0.0317 | G34: =Data!F60 -> -0.1623 | H34: =(G33/C33)^(1/4)-1 -> 0.03980228 | I34: =H34 -> 0.03980228 | J34: =I34 -> 0.03980228 | K34: =J34 -> 0.03980228 | L34: =K34 -> 0.03980228
B35: EBITDA Margin | C35: =Data!B61 -> - | D35: =Data!C61 -> - | E35: =Data!D61 -> - | F35: =Data!E61 -> - | G35: =Data!F61 -> 0.116
B38: Pretax Income | C38: =Data!B30 -> 6.34B | D38: =Data!C30 -> 13.72B | E38: =Data!D30 -> 9.97B | F38: =Data!E30 -> 8.99B | G38: =Data!F30 -> 5.28B | H38: - | I38: - | J38: - | K38: - | L38: -
B39: Income Tax | C39: =Data!B33 -> 699M | D39: =Data!C33 -> 1.13B | E39: =Data!D33 -> (5B) | F39: =Data!E33 -> 1.84B | G39: =Data!F33 -> 1.42B | H39: - | I39: - | J39: - | K39: - | L39: -
B40: Net Income | C40: =IFERROR(__xludf.DUMMYFUNCTION("IFERROR( LET( x, UPPER(SUBSTITUTE(TRIM(Data!B43),CHAR(160),"""")), base, VALUE(SUBSTITUTE(REGEXEXTRACT(x,""[0-9.,]+""),"","","""")), mult, IF(REGEXMATCH(x,""B""),1000000000, IF(REGEXMATCH(x,""M""),1000000, 1)), base * mult ), 0 )"),5.52E9) -> 5520000000 | D40: =IFERROR(__xludf.DUMMYFUNCTION("IFERROR( LET( x, UPPER(SUBSTITUTE(TRIM(Data!C43),CHAR(160),"""")), base, VALUE(SUBSTITUTE(REGEXEXTRACT(x,""[0-9.,]+""),"","","""")), mult, IF(REGEXMATCH(x,""B""),1000000000, IF(REGEXMATCH(x,""M""),1000000, 1)), base * mult ), 0 )"),1.258E10) -> 12580000000 | E40: =IFERROR(__xludf.DUMMYFUNCTION("IFERROR( LET( x, UPPER(SUBSTITUTE(TRIM(Data!D43),CHAR(160),"""")), base, VALUE(SUBSTITUTE(REGEXEXTRACT(x,""[0-9.,]+""),"","","""")), mult, IF(REGEXMATCH(x,""B""),1000000000, IF(REGEXMATCH(x,""M""),1000000, 1)), base * mult ), 0 )"),1.5E10) -> 15000000000 | F40: =IFERROR(__xludf.DUMMYFUNCTION("IFERROR( LET( x, UPPER(SUBSTITUTE(TRIM(Data!E43),CHAR(160),"""")), base, VALUE(SUBSTITUTE(REGEXEXTRACT(x,""[0-9.,]+""),"","","""")), mult, IF(REGEXMATCH(x,""B""),1000000000, IF(REGEXMATCH(x,""M""),1000000, 1)), base * mult ), 0 )"),7.13E9) -> 7130000000 | G40: =IFERROR(__xludf.DUMMYFUNCTION("IFERROR( LET( x, UPPER(SUBSTITUTE(TRIM(Data!F43),CHAR(160),"""")), base, VALUE(SUBSTITUTE(REGEXEXTRACT(x,""[0-9.,]+""),"","","""")), mult, IF(REGEXMATCH(x,""B""),1000000000, IF(REGEXMATCH(x,""M""),1000000, 1)), base * mult ), 0 )"),3.79E9) -> 3790000000 | H40: =G40*(1+H42) -> 2778701667 | I40: =H40*(1+I42) -> 2037251439 | J40: =I40*(1+J42) -> 1259955129 | K40: =J40*(1+K42) -> 8.2429152e+08 | L40: =K40*(1+L42) -> 5.6443662e+08
B41: Net Income to Common | C41: =Data!B52 -> 5.52B | D41: =Data!C52 -> 12.58B | E41: =Data!D52 -> 15B | F41: =Data!E52 -> 7.13B | G41: =Data!F52 -> 3.79B | H41: - | I41: - | J41: - | K41: - | L41: -
B42: Net Income Growth | C42: =Data!B44 -> - | D42: =Data!C44 -> 1.2779 | E42: =Data!D44 -> 0.192 | F42: =Data!E44 -> -0.5246 | G42: =Data!F44 -> -0.4679 | H42: =AVERAGEIF(D42:G42,"<0.70") -> -0.26683333 | I42: =AVERAGEIF(E42:H42,"<0.80") -> -0.26683333 | J42: =AVERAGEIF(F42:I42,"<0.80") -> -0.38154167 | K42: =AVERAGEIF(G42:J42,"<0.80") -> -0.34577708 | L42: =AVERAGEIF(H42:K42,"<0.80") -> -0.31524635
B45: EPS (Diluted) | C45: =Data!B56 -> 1.63 | D45: =Data!C56 -> 3.62 | E45: =Data!D56 -> 4.3 | F45: =Data!E56 -> 2.04 | G45: =Data!F56 -> 1.08 | H45: =Forecast(H12,$C$45:G45,$C$12:G12) -> 1.73 | I45: =FORECAST(I12,$C$45:H45,$C$12:H12) -> 1.462 | J45: =FORECAST(J12,$C$45:I45,$C$12:I12) -> 1.194 | K45: =FORECAST(K12,$C$45:J45,$C$12:J12) -> 0.926 | L45: =FORECAST(L12,$C$45:K45,$C$12:K12) -> 0.658
B46: EPS (Diluted) Growth | C46: =Data!B57 -> - | D46: =Data!C57 -> 1.2204 | E46: =Data!D57 -> 0.1885 | F46: =Data!E57 -> -0.5264 | G46: =Data!F57 -> -0.4724 | H46: =H45/G45-1 -> 0.60185185 | I46: =I45/H45-1 -> -0.15491329 | J46: =J45/I45-1 -> -0.18331053 | K46: =K45/J45-1 -> -0.22445561 | L46: =L45/K45-1 -> -0.28941685
D1006: =1.56*L33 -> 20857925440

Sheet Balance Sheet
B2: Balance Sheet | C2: FY | H2: Future FY
C3: 2021 | D3: =C3+1 -> 2022 | E3: =D3+1 -> 2023 | F3: =E3+1 -> 2024 | G3: =F3+1 -> 2025 | H3: =G3+1 -> 2026 | I3: =H3+1 -> 2027 | J3: =I3+1 -> 2028 | K3: =J3+1 -> 2029 | L3: =K3+1 -> 2030
B6: Cash Only | C6: =IFERROR(__xludf.DUMMYFUNCTION("IFERROR( LET( x, UPPER(SUBSTITUTE(TRIM(Data!B71),CHAR(160),"""")), base, VALUE(SUBSTITUTE(REGEXEXTRACT(x,""[0-9.,]+""),"","","""")), mult, IF(REGEXMATCH(x,""B""),1000000000, IF(REGEXMATCH(x,""M""),1000000, 1)), base * mult ), 0 )"),1.792E10) -> 17920000000 | D6: =IFERROR(__xludf.DUMMYFUNCTION("IFERROR( LET( x, UPPER(SUBSTITUTE(TRIM(Data!C71),CHAR(160),"""")), base, VALUE(SUBSTITUTE(REGEXEXTRACT(x,""[0-9.,]+""),"","","""")), mult, IF(REGEXMATCH(x,""B""),1000000000, IF(REGEXMATCH(x,""M""),1000000, 1)), base * mult ), 0 )"),1.655E10) -> 16550000000 | E6: =IFERROR(__xludf.DUMMYFUNCTION("IFERROR( LET( x, UPPER(SUBSTITUTE(TRIM(Data!D71),CHAR(160),"""")), base, VALUE(SUBSTITUTE(REGEXEXTRACT(x,""[0-9.,]+""),"","","""")), mult, IF(REGEXMATCH(x,""B""),1000000000, IF(REGEXMATCH(x,""M""),1000000, 1)), base * mult ), 0 )"),1.6940000000000002E10) -> 16940000000 | F6: =IFERROR(__xludf.DUMMYFUNCTION("IFERROR( LET( x, UPPER(SUBSTITUTE(TRIM(Data!E71),CHAR(160),"""")), base, VALUE(SUBSTITUTE(REGEXEXTRACT(x,""[0-9.,]+""),"","","""")), mult, IF(REGEXMATCH(x,""B""),1000000000, IF(REGEXMATCH(x,""M""),1000000, 1)), base * mult ), 0 )"),1.6629999999999998E10) -> 16630000000 | G6: =IFERROR(__xludf.DUMMYFUNCTION("IFERROR( LET( x, UPPER(SUBSTITUTE(TRIM(Data!F71),CHAR(160),"""")), base, VALUE(SUBSTITUTE(REGEXEXTRACT(x,""[0-9.,]+""),"","","""")), mult, IF(REGEXMATCH(x,""B""),1000000000, IF(REGEXMATCH(x,""M""),1000000, 1)), base * mult ), 0 )"),1.6899999999999998E10) -> 16900000000 | H6: =FORECAST(H3,$C$6:G6,$C$3:G3) -> 16400000000 | I6: =FORECAST(I3,$C$6:H6,$C$3:H3) -> 16204000000 | J6: =FORECAST(J3,$C$6:I6,$C$3:I3) -> 16008000000 | K6: =FORECAST(K3,$C$6:J6,$C$3:J3) -> 15812000000 | L6: =FORECAST(L3,$C$6:K6,$C$3:K3) -> 15616000000
B7: Short-Term Investments | C7: =Data!B72:F72 -> - | D7: =Data!C72 -> - | E7: =Data!D72 -> - | F7: =Data!E72 -> - | G7: =Data!F72 -> - | H7: - | I7: - | J7: - | K7: - | L7: -
B8: Cash & Short Term Invesments | C8: =IFERROR(__xludf.DUMMYFUNCTION("IFERROR( LET( x, UPPER(SUBSTITUTE(TRIM(Data!B69),CHAR(160),"""")), base, VALUE(SUBSTITUTE(REGEXEXTRACT(x,""[0-9.,]+""),"","","""")), mult, IF(REGEXMATCH(x,""B""),1000000000, IF(REGEXMATCH(x,""M""),1000000, 1)), base * mult ), 0 )"),1.805E10) -> 18050000000 | D8: =IFERROR(__xludf.DUMMYFUNCTION("IFERROR( LET( x, UPPER(SUBSTITUTE(TRIM(Data!C69),CHAR(160),"""")), base, VALUE(SUBSTITUTE(REGEXEXTRACT(x,""[0-9.,]+""),"","","""")), mult, IF(REGEXMATCH(x,""B""),1000000000, IF(REGEXMATCH(x,""M""),1000000, 1)), base * mult ), 0 )"),2.248E10) -> 22480000000 | E8: =IFERROR(__xludf.DUMMYFUNCTION("IFERROR( LET( x, UPPER(SUBSTITUTE(TRIM(Data!D69),CHAR(160),"""")), base, VALUE(SUBSTITUTE(REGEXEXTRACT(x,""[0-9.,]+""),"","","""")), mult, IF(REGEXMATCH(x,""B""),1000000000, IF(REGEXMATCH(x,""M""),1000000, 1)), base * mult ), 0 )"),2.964E10) -> 29640000000 | F8: =IFERROR(__xludf.DUMMYFUNCTION("IFERROR( LET( x, UPPER(SUBSTITUTE(TRIM(Data!E69),CHAR(160),"""")), base, VALUE(SUBSTITUTE(REGEXEXTRACT(x,""[0-9.,]+""),"","","""")), mult, IF(REGEXMATCH(x,""B""),1000000000, IF(REGEXMATCH(x,""M""),1000000, 1)), base * mult ), 0 )"),3.706E10) -> 37060000000 | G8: =IFERROR(__xludf.DUMMYFUNCTION("IFERROR( LET( x, UPPER(SUBSTITUTE(TRIM(Data!F69),CHAR(160),"""")), base, VALUE(SUBSTITUTE(REGEXEXTRACT(x,""[0-9.,]+""),"","","""")), mult, IF(REGEXMATCH(x,""B""),1000000000, IF(REGEXMATCH(x,""M""),1000000, 1)), base * mult ), 0 )"),4.445E10) -> 44450000000 | H8: =H6 -> 16400000000 | I8: =I6 -> 16204000000 | J8: =J6 -> 16008000000 | K8: =K6 -> 15812000000 | L8: =L6 -> 15616000000
B9: Cash & Short Term Invesments Growth | C9: =Data!B70 -> - | D9: =Data!C70 -> 0.2452 | E9: =Data!D70 -> 0.3184 | F9: =Data!E70 -> 0.2504 | G9: =Data!F70 -> 0.1994 | H9: =H8/G8-1 -> -0.63104612 | I9: =I8/H8-1 -> -0.01195122 | J9: =J8/I8-1 -> -0.012095779 | K9: =K8/J8-1 -> -0.012243878 | L9: =L8/K8-1 -> -0.012395649
B12: Finished Goods | C12: =IFERROR(__xludf.DUMMYFUNCTION("IFERROR( LET( x, UPPER(SUBSTITUTE(TRIM(Data!B82),CHAR(160),"""")), base, VALUE(SUBSTITUTE(REGEXEXTRACT(x,""[0-9.,]+""),"","","""")), mult, IF(REGEXMATCH(x,""B""),1000000000, IF(REGEXMATCH(x,""M""),1000000, 1)), base * mult ), 0 )"),1.28E9) -> 1280000000 | D12: =IFERROR(__xludf.DUMMYFUNCTION("IFERROR( LET( x, UPPER(SUBSTITUTE(TRIM(Data!C82),CHAR(160),"""")), base, VALUE(SUBSTITUTE(REGEXEXTRACT(x,""[0-9.,]+""),"","","""")), mult, IF(REGEXMATCH(x,""B""),1000000000, IF(REGEXMATCH(x,""M""),1000000, 1)), base * mult ), 0 )"),3.48E9) -> 3480000000 | E12: =IFERROR(__xludf.DUMMYFUNCTION("IFERROR( LET( x, UPPER(SUBSTITUTE(TRIM(Data!D82),CHAR(160),"""")), base, VALUE(SUBSTITUTE(REGEXEXTRACT(x,""[0-9.,]+""),"","","""")), mult, IF(REGEXMATCH(x,""B""),1000000000, IF(REGEXMATCH(x,""M""),1000000, 1)), base * mult ), 0 )"),5.05E9) -> 5050000000 | F12: =IFERROR(__xludf.DUMMYFUNCTION("IFERROR( LET( x, UPPER(SUBSTITUTE(TRIM(Data!E82),CHAR(160),"""")), base, VALUE(SUBSTITUTE(REGEXEXTRACT(x,""[0-9.,]+""),"","","""")), mult, IF(REGEXMATCH(x,""B""),1000000000, IF(REGEXMATCH(x,""M""),1000000, 1)), base * mult ), 0 )"),3.94E9) -> 3940000000 | G12: =IFERROR(__xludf.DUMMYFUNCTION("IFERROR( LET( x, UPPER(SUBSTITUTE(TRIM(Data!F82),CHAR(160),"""")), base, VALUE(SUBSTITUTE(REGEXEXTRACT(x,""[0-9.,]+""),"","","""")), mult, IF(REGEXMATCH(x,""B""),1000000000, IF(REGEXMATCH(x,""M""),1000000, 1)), base * mult ), 0 )"),4.85E9) -> 4850000000 | H12: =AVERAGE(C12:G12) -> 3720000000 | I12: =AVERAGE(D12:H12) -> 4208000000 | J12: =AVERAGE(E12:I12) -> 4353600000 | K12: =AVERAGE(F12:J12) -> 4214320000 | L12: =AVERAGE(G12:K12) -> 4269184000
B13: Work in Progress | C13: =IFERROR(__xludf.DUMMYFUNCTION("regexreplace(Data!B83,""M"","""")*1000000"),"#VALUE!") -> #VALUE! | D13: =IFERROR(__xludf.DUMMYFUNCTION("IFERROR( LET( x, UPPER(SUBSTITUTE(TRIM(Data!C83),CHAR(160),"""")), base, VALUE(SUBSTITUTE(REGEXEXTRACT(x,""[0-9.,]+""),"","","""")), mult, IF(REGEXMATCH(x,""B""),1000000000, IF(REGEXMATCH(x,""M""),1000000, 1)), base * mult ), 0 )"),2.39E9) -> 2390000000 | E13: =IFERROR(__xludf.DUMMYFUNCTION("IFERROR( LET( x, UPPER(SUBSTITUTE(TRIM(Data!D83),CHAR(160),"""")), base, VALUE(SUBSTITUTE(REGEXEXTRACT(x,""[0-9.,]+""),"","","""")), mult, IF(REGEXMATCH(x,""B""),1000000000, IF(REGEXMATCH(x,""M""),1000000, 1)), base * mult ), 0 )"),2.02E9) -> 2020000000 | F13: =IFERROR(__xludf.DUMMYFUNCTION("IFERROR( LET( x, UPPER(SUBSTITUTE(TRIM(Data!E83),CHAR(160),"""")), base, VALUE(SUBSTITUTE(REGEXEXTRACT(x,""[0-9.,]+""),"","","""")), mult, IF(REGEXMATCH(x,""B""),1000000000, IF(REGEXMATCH(x,""M""),1000000, 1)), base * mult ), 0 )"),1.53E9) -> 1530000000 | G13: =IFERROR(__xludf.DUMMYFUNCTION("IFERROR( LET( x, UPPER(SUBSTITUTE(TRIM(Data!F83),CHAR(160),"""")), base, VALUE(SUBSTITUTE(REGEXEXTRACT(x,""[0-9.,]+""),"","","""")), mult, IF(REGEXMATCH(x,""B""),1000000000, IF(REGEXMATCH(x,""M""),1000000, 1)), base * mult ), 0 )"),1.73E9) -> 1730000000 | H13: =AVERAGE(C13:G13) -> #VALUE! | I13: =AVERAGE(D13:H13) -> #VALUE! | J13: =AVERAGE(E13:I13) -> #VALUE! | K13: =AVERAGE(F13:J13) -> #VALUE! | L13: =AVERAGE(G13:K13) -> #VALUE!
B14: Raw Materials | C14: =IFERROR(__xludf.DUMMYFUNCTION("IFERROR( LET( x, UPPER(SUBSTITUTE(TRIM(Data!B84),CHAR(160),"""")), base, VALUE(SUBSTITUTE(REGEXEXTRACT(x,""[0-9.,]+""),"","","""")), mult, IF(REGEXMATCH(x,""B""),1000000000, IF(REGEXMATCH(x,""M""),1000000, 1)), base * mult ), 0 )"),3.39E9) -> 3390000000 | D14: =IFERROR(__xludf.DUMMYFUNCTION("IFERROR( LET( x, UPPER(SUBSTITUTE(TRIM(Data!C84),CHAR(160),"""")), base, VALUE(SUBSTITUTE(REGEXEXTRACT(x,""[0-9.,]+""),"","","""")), mult, IF(REGEXMATCH(x,""B""),1000000000, IF(REGEXMATCH(x,""M""),1000000, 1)), base * mult ), 0 )"),6.98E9) -> 6980000000 | E14: =IFERROR(__xludf.DUMMYFUNCTION("IFERROR( LET( x, UPPER(SUBSTITUTE(TRIM(Data!D84),CHAR(160),"""")), base, VALUE(SUBSTITUTE(REGEXEXTRACT(x,""[0-9.,]+""),"","","""")), mult, IF(REGEXMATCH(x,""B""),1000000000, IF(REGEXMATCH(x,""M""),1000000, 1)), base * mult ), 0 )"),6.56E9) -> 6560000000 | F14: =IFERROR(__xludf.DUMMYFUNCTION("IFERROR( LET( x, UPPER(SUBSTITUTE(TRIM(Data!E84),CHAR(160),"""")), base, VALUE(SUBSTITUTE(REGEXEXTRACT(x,""[0-9.,]+""),"","","""")), mult, IF(REGEXMATCH(x,""B""),1000000000, IF(REGEXMATCH(x,""M""),1000000, 1)), base * mult ), 0 )"),6.55E9) -> 6550000000 | G14: =IFERROR(__xludf.DUMMYFUNCTION("IFERROR( LET( x, UPPER(SUBSTITUTE(TRIM(Data!F84),CHAR(160),"""")), base, VALUE(SUBSTITUTE(REGEXEXTRACT(x,""[0-9.,]+""),"","","""")), mult, IF(REGEXMATCH(x,""B""),1000000000, IF(REGEXMATCH(x,""M""),1000000, 1)), base * mult ), 0 )"),5.82E9) -> 5820000000 | H14: =AVERAGE(C14:G14) -> 5860000000 | I14: =AVERAGE(D14:H14) -> 6354000000 | J14: =AVERAGE(E14:I14) -> 6228800000 | K14: =AVERAGE(F14:J14) -> 6162560000 | L14: =AVERAGE(G14:K14) -> 6085072000
B15: Inventories | C15: =IFERROR(__xludf.DUMMYFUNCTION("IFERROR( LET( x, UPPER(SUBSTITUTE(TRIM(Data!B81),CHAR(160),"""")), base, VALUE(SUBSTITUTE(REGEXEXTRACT(x,""[0-9.,]+""),"","","""")), mult, IF(REGEXMATCH(x,""B""),1000000000, IF(REGEXMATCH(x,""M""),1000000, 1)), base * mult ), 0 )"),5.76E9) -> 5760000000 | D15: =IFERROR(__xludf.DUMMYFUNCTION("IFERROR( LET( x, UPPER(SUBSTITUTE(TRIM(Data!C81),CHAR(160),"""")), base, VALUE(SUBSTITUTE(REGEXEXTRACT(x,""[0-9.,]+""),"","","""")), mult, IF(REGEXMATCH(x,""B""),1000000000, IF(REGEXMATCH(x,""M""),1000000, 1)), base * mult ), 0 )"),1.284E10) -> 12840000000 | E15: =IFERROR(__xludf.DUMMYFUNCTION("IFERROR( LET( x, UPPER(SUBSTITUTE(TRIM(Data!D81),CHAR(160),"""")), base, VALUE(SUBSTITUTE(REGEXEXTRACT(x,""[0-9.,]+""),"","","""")), mult, IF(REGEXMATCH(x,""B""),1000000000, IF(REGEXMATCH(x,""M""),1000000, 1)), base * mult ), 0 )"),1.363E10) -> 13630000000 | F15: =IFERROR(__xludf.DUMMYFUNCTION("IFERROR( LET( x, UPPER(SUBSTITUTE(TRIM(Data!E81),CHAR(160),"""")), base, VALUE(SUBSTITUTE(REGEXEXTRACT(x,""[0-9.,]+""),"","","""")), mult, IF(REGEXMATCH(x,""B""),1000000000, IF(REGEXMATCH(x,""M""),1000000, 1)), base * mult ), 0 )"),1.202E10) -> 12020000000 | G15: =IFERROR(__xludf.DUMMYFUNCTION("IFERROR( LET( x, UPPER(SUBSTITUTE(TRIM(Data!F81),CHAR(160),"""")), base, VALUE(SUBSTITUTE(REGEXEXTRACT(x,""[0-9.,]+""),"","","""")), mult, IF(REGEXMATCH(x,""B""),1000000000, IF(REGEXMATCH(x,""M""),1000000, 1)), base * mult ), 0 )"),1.239E10) -> 12390000000 | H15: =AVERAGE(C15:G15) -> 11328000000 | I15: =AVERAGE(D15:H15) -> 12441600000 | J15: =AVERAGE(E15:I15) -> 12361920000 | K15: =AVERAGE(F15:J15) -> 12108304000 | L15: =AVERAGE(G15:K15) -> 12125964800
B18: Accounts Receivables, Net | C18: =IFERROR(__xludf.DUMMYFUNCTION("IFERROR( LET( x, UPPER(SUBSTITUTE(TRIM(Data!B76),CHAR(160),"""")), base, VALUE(SUBSTITUTE(REGEXEXTRACT(x,""[0-9.,]+""),"","","""")), mult, IF(REGEXMATCH(x,""B""),1000000000, IF(REGEXMATCH(x,""M""),1000000, 1)), base * mult ), 0 )"),1.91E9) -> 1910000000 | D18: =IFERROR(__xludf.DUMMYFUNCTION("IFERROR( LET( x, UPPER(SUBSTITUTE(TRIM(Data!C76),CHAR(160),"""")), base, VALUE(SUBSTITUTE(REGEXEXTRACT(x,""[0-9.,]+""),"","","""")), mult, IF(REGEXMATCH(x,""B""),1000000000, IF(REGEXMATCH(x,""M""),1000000, 1)), base * mult ), 0 )"),2.95E9) -> 2950000000 | E18: =IFERROR(__xludf.DUMMYFUNCTION("IFERROR( LET( x, UPPER(SUBSTITUTE(TRIM(Data!D76),CHAR(160),"""")), base, VALUE(SUBSTITUTE(REGEXEXTRACT(x,""[0-9.,]+""),"","","""")), mult, IF(REGEXMATCH(x,""B""),1000000000, IF(REGEXMATCH(x,""M""),1000000, 1)), base * mult ), 0 )"),3.51E9) -> 3510000000 | F18: =IFERROR(__xludf.DUMMYFUNCTION("IFERROR( LET( x, UPPER(SUBSTITUTE(TRIM(Data!E76),CHAR(160),"""")), base, VALUE(SUBSTITUTE(REGEXEXTRACT(x,""[0-9.,]+""),"","","""")), mult, IF(REGEXMATCH(x,""B""),1000000000, IF(REGEXMATCH(x,""M""),1000000, 1)), base * mult ), 0 )"),4.42E9) -> 4420000000 | G18: =IFERROR(__xludf.DUMMYFUNCTION("IFERROR( LET( x, UPPER(SUBSTITUTE(TRIM(Data!F76),CHAR(160),"""")), base, VALUE(SUBSTITUTE(REGEXEXTRACT(x,""[0-9.,]+""),"","","""")), mult, IF(REGEXMATCH(x,""B""),1000000000, IF(REGEXMATCH(x,""M""),1000000, 1)), base * mult ), 0 )"),4.58E9) -> 4580000000 | H18: =FORECAST(H3,$C$18:G18,$C$3:G3) -> 5517000000 | I18: =FORECAST(I3,$C$18:H18,$C$3:H3) -> 6198000000 | J18: =FORECAST(J3,$C$18:I18,$C$3:I3) -> 6879000000 | K18: =FORECAST(K3,$C$18:J18,$C$3:J3) -> 7560000000 | L18: =FORECAST(L3,$C$18:K18,$C$3:K3) -> 8241000000
B19: Other Receivable | C19: =Data!B79 -> - | D19: =Data!C79 -> - | E19: =Data!D79 -> - | F19: =Data!E79 -> - | G19: =Data!F79 -> 130M | H19: - | I19: - | J19: - | K19: - | L19: -
B20: Total Accounts Receivable | C20: =IFERROR(__xludf.DUMMYFUNCTION("IFERROR( LET( x, UPPER(SUBSTITUTE(TRIM(Data!B74),CHAR(160),"""")), base, VALUE(SUBSTITUTE(REGEXEXTRACT(x,""[0-9.,]+""),"","","""")), mult, IF(REGEXMATCH(x,""B""),1000000000, IF(REGEXMATCH(x,""M""),1000000, 1)), base * mult ), 0 )"),1.91E9) -> 1910000000 | D20: =IFERROR(__xludf.DUMMYFUNCTION("IFERROR( LET( x, UPPER(SUBSTITUTE(TRIM(Data!C74),CHAR(160),"""")), base, VALUE(SUBSTITUTE(REGEXEXTRACT(x,""[0-9.,]+""),"","","""")), mult, IF(REGEXMATCH(x,""B""),1000000000, IF(REGEXMATCH(x,""M""),1000000, 1)), base * mult ), 0 )"),2.95E9) -> 2950000000 | E20: =IFERROR(__xludf.DUMMYFUNCTION("IFERROR( LET( x, UPPER(SUBSTITUTE(TRIM(Data!D74),CHAR(160),"""")), base, VALUE(SUBSTITUTE(REGEXEXTRACT(x,""[0-9.,]+""),"","","""")), mult, IF(REGEXMATCH(x,""B""),1000000000, IF(REGEXMATCH(x,""M""),1000000, 1)), base * mult ), 0 )"),3.51E9) -> 3510000000 | F20: =IFERROR(__xludf.DUMMYFUNCTION("IFERROR( LET( x, UPPER(SUBSTITUTE(TRIM(Data!E74),CHAR(160),"""")), base, VALUE(SUBSTITUTE(REGEXEXTRACT(x,""[0-9.,]+""),"","","""")), mult, IF(REGEXMATCH(x,""B""),1000000000, IF(REGEXMATCH(x,""M""),1000000, 1)), base * mult ), 0 )"),4.42E9) -> 4420000000 | G20: =IFERROR(__xludf.DUMMYFUNCTION("IFERROR( LET( x, UPPER(SUBSTITUTE(TRIM(Data!F74),CHAR(160),"""")), base, VALUE(SUBSTITUTE(REGEXEXTRACT(x,""[0-9.,]+""),"","","""")), mult, IF(REGEXMATCH(x,""B""),1000000000, IF(REGEXMATCH(x,""M""),1000000, 1)), base * mult ), 0 )"),4.71E9) -> 4710000000 | H20: =FORECAST(H3,$C$20:G20,$C$3:G3) -> 5621000000 | I20: =FORECAST(I3,$C$20:H20,$C$3:H3) -> 6328000000 | J20: =FORECAST(J3,$C$20:I20,$C$3:I3) -> 7035000000 | K20: =FORECAST(K3,$C$20:J20,$C$3:J3) -> 7742000000 | L20: =FORECAST(L3,$C$20:K20,$C$3:K3) -> 8449000000
B21: Total Accounts Receivable Growth | C21: =Data!B75 -> - | D21: =Data!C75 -> 0.5431 | E21: =Data!D75 -> 0.1883 | F21: =Data!E75 -> 0.2594 | G21: =Data!F75 -> 0.0652 | H21: =H20/G20-1 -> 0.19341826 | I21: =I20/H20-1 -> 0.12577833 | J21: =J20/I20-1 -> 0.11172566 | K21: =K20/J20-1 -> 0.10049751 | L21: =L20/K20-1 -> 0.091320072
B24: Other Current Assets | C24: =IFERROR(__xludf.DUMMYFUNCTION("IFERROR( LET( x, UPPER(SUBSTITUTE(TRIM(Data!B86),CHAR(160),"""")), base, VALUE(SUBSTITUTE(REGEXEXTRACT(x,""[0-9.,]+""),"","","""")), mult, IF(REGEXMATCH(x,""B""),1000000000, IF(REGEXMATCH(x,""M""),1000000, 1)), base * mult ), 0 )"),1.38E9) -> 1380000000 | D24: =IFERROR(__xludf.DUMMYFUNCTION("IFERROR( LET( x, UPPER(SUBSTITUTE(TRIM(Data!C86),CHAR(160),"""")), base, VALUE(SUBSTITUTE(REGEXEXTRACT(x,""[0-9.,]+""),"","","""")), mult, IF(REGEXMATCH(x,""B""),1000000000, IF(REGEXMATCH(x,""M""),1000000, 1)), base * mult ), 0 )"),2.65E9) -> 2650000000 | E24: =IFERROR(__xludf.DUMMYFUNCTION("IFERROR( LET( x, UPPER(SUBSTITUTE(TRIM(Data!D86),CHAR(160),"""")), base, VALUE(SUBSTITUTE(REGEXEXTRACT(x,""[0-9.,]+""),"","","""")), mult, IF(REGEXMATCH(x,""B""),1000000000, IF(REGEXMATCH(x,""M""),1000000, 1)), base * mult ), 0 )"),2.85E9) -> 2850000000 | F24: =IFERROR(__xludf.DUMMYFUNCTION("IFERROR( LET( x, UPPER(SUBSTITUTE(TRIM(Data!E86),CHAR(160),"""")), base, VALUE(SUBSTITUTE(REGEXEXTRACT(x,""[0-9.,]+""),"","","""")), mult, IF(REGEXMATCH(x,""B""),1000000000, IF(REGEXMATCH(x,""M""),1000000, 1)), base * mult ), 0 )"),4.87E9) -> 4870000000 | G24: =IFERROR(__xludf.DUMMYFUNCTION("IFERROR( LET( x, UPPER(SUBSTITUTE(TRIM(Data!F86),CHAR(160),"""")), base, VALUE(SUBSTITUTE(REGEXEXTRACT(x,""[0-9.,]+""),"","","""")), mult, IF(REGEXMATCH(x,""B""),1000000000, IF(REGEXMATCH(x,""M""),1000000, 1)), base * mult ), 0 )"),7.1E9) -> 7100000000 | H24: =AVERAGE(C24:G24) -> 3770000000 | I24: =AVERAGE(D24:H24) -> 4248000000 | J24: =AVERAGE(E24:I24) -> 4567600000 | K24: =AVERAGE(F24:J24) -> 4911120000 | L24: =AVERAGE(G24:K24) -> 4919344000
B25: Total Current Assets | C25: =IFERROR(__xludf.DUMMYFUNCTION("IFERROR( LET( x, UPPER(SUBSTITUTE(TRIM(Data!B88),CHAR(160),"""")), base, VALUE(SUBSTITUTE(REGEXEXTRACT(x,""[0-9.,]+""),"","","""")), mult, IF(REGEXMATCH(x,""B""),1000000000, IF(REGEXMATCH(x,""M""),1000000, 1)), base * mult ), 0 )"),2.71E10) -> 27100000000 | D25: =IFERROR(__xludf.DUMMYFUNCTION("IFERROR( LET( x, UPPER(SUBSTITUTE(TRIM(Data!C88),CHAR(160),"""")), base, VALUE(SUBSTITUTE(REGEXEXTRACT(x,""[0-9.,]+""),"","","""")), mult, IF(REGEXMATCH(x,""B""),1000000000, IF(REGEXMATCH(x,""M""),1000000, 1)), base * mult ), 0 )"),4.092E10) -> 40920000000 | E25: =IFERROR(__xludf.DUMMYFUNCTION("IFERROR( LET( x, UPPER(SUBSTITUTE(TRIM(Data!D88),CHAR(160),"""")), base, VALUE(SUBSTITUTE(REGEXEXTRACT(x,""[0-9.,]+""),"","","""")), mult, IF(REGEXMATCH(x,""B""),1000000000, IF(REGEXMATCH(x,""M""),1000000, 1)), base * mult ), 0 )"),4.962E10) -> 49620000000 | F25: =IFERROR(__xludf.DUMMYFUNCTION("IFERROR( LET( x, UPPER(SUBSTITUTE(TRIM(Data!E88),CHAR(160),"""")), base, VALUE(SUBSTITUTE(REGEXEXTRACT(x,""[0-9.,]+""),"","","""")), mult, IF(REGEXMATCH(x,""B""),1000000000, IF(REGEXMATCH(x,""M""),1000000, 1)), base * mult ), 0 )"),5.836E10) -> 58360000000 | G25: =IFERROR(__xludf.DUMMYFUNCTION("IFERROR( LET( x, UPPER(SUBSTITUTE(TRIM(Data!F88),CHAR(160),"""")), base, VALUE(SUBSTITUTE(REGEXEXTRACT(x,""[0-9.,]+""),"","","""")), mult, IF(REGEXMATCH(x,""B""),1000000000, IF(REGEXMATCH(x,""M""),1000000, 1)), base * mult ), 0 )"),6.864E10) -> 68640000000 | H25: =FORECAST(H3,$C$25:G25,$C$3:G3) -> 79084000000 | I25: =FORECAST(I3,$C$25:H25,$C$3:H3) -> 89136000000 | J25: =FORECAST(J3,$C$25:I25,$C$3:I3) -> 99188000000 | K25: =FORECAST(K3,$C$25:J25,$C$3:J3) -> 109240000000 | L25: =FORECAST(L3,$C$25:K25,$C$3:K3) -> 119292000000
B26: Total Current Assets Growth | C26: - | D26: =D25/C25-1 -> 0.5099631 | E26: =E25/D25-1 -> 0.21260997 | F26: =F25/E25-1 -> 0.17613865 | G26: =G25/F25-1 -> 0.17614805 | H26: =H25/G25-1 -> 0.15215618 | I26: =I25/H25-1 -> 0.12710536 | J26: =J25/I25-1 -> 0.1127715 | K26: =K25/J25-1 -> 0.1013429 | L26: =L25/K25-1 -> 0.092017576
B29: Property, Plant & Equipment | C29: =IFERROR(__xludf.DUMMYFUNCTION("IFERROR( LET( x, UPPER(SUBSTITUTE(TRIM(Data!B90),CHAR(160),"""")), base, VALUE(SUBSTITUTE(REGEXEXTRACT(x,""[0-9.,]+""),"","","""")), mult, IF(REGEXMATCH(x,""B""),1000000000, IF(REGEXMATCH(x,""M""),1000000, 1)), base * mult ), 0 )"),3.987E10) -> 39870000000 | D29: =IFERROR(__xludf.DUMMYFUNCTION("IFERROR( LET( x, UPPER(SUBSTITUTE(TRIM(Data!C90),CHAR(160),"""")), base, VALUE(SUBSTITUTE(REGEXEXTRACT(x,""[0-9.,]+""),"","","""")), mult, IF(REGEXMATCH(x,""B""),1000000000, IF(REGEXMATCH(x,""M""),1000000, 1)), base * mult ), 0 )"),4.813E10) -> 48130000000 | E29: =IFERROR(__xludf.DUMMYFUNCTION("IFERROR( LET( x, UPPER(SUBSTITUTE(TRIM(Data!D90),CHAR(160),"""")), base, VALUE(SUBSTITUTE(REGEXEXTRACT(x,""[0-9.,]+""),"","","""")), mult, IF(REGEXMATCH(x,""B""),1000000000, IF(REGEXMATCH(x,""M""),1000000, 1)), base * mult ), 0 )"),6.02E10) -> 60200000000 | F29: =IFERROR(__xludf.DUMMYFUNCTION("IFERROR( LET( x, UPPER(SUBSTITUTE(TRIM(Data!E90),CHAR(160),"""")), base, VALUE(SUBSTITUTE(REGEXEXTRACT(x,""[0-9.,]+""),"","","""")), mult, IF(REGEXMATCH(x,""B""),1000000000, IF(REGEXMATCH(x,""M""),1000000, 1)), base * mult ), 0 )"),7.04E10) -> 70400000000 | G29: =IFERROR(__xludf.DUMMYFUNCTION("IFERROR( LET( x, UPPER(SUBSTITUTE(TRIM(Data!F90),CHAR(160),"""")), base, VALUE(SUBSTITUTE(REGEXEXTRACT(x,""[0-9.,]+""),"","","""")), mult, IF(REGEXMATCH(x,""B""),1000000000, IF(REGEXMATCH(x,""M""),1000000, 1)), base * mult ), 0 )"),7.963E10) -> 79630000000 | H29: =AVERAGE(C29:G29) -> 59646000000 | I29: =AVERAGE(D29:H29) -> 63601200000 | J29: =AVERAGE(E29:I29) -> 66695440000 | K29: =AVERAGE(F29:J29) -> 67994528000 | L29: =AVERAGE(G29:K29) -> 67513433600
B30: Accumulated Depreciation | C30: =IFERROR(__xludf.DUMMYFUNCTION("IFERROR( LET( x, UPPER(SUBSTITUTE(TRIM(Data!B95),CHAR(160),"""")), base, VALUE(SUBSTITUTE(REGEXEXTRACT(x,""[0-9.,]+""),"","","""")), mult, IF(REGEXMATCH(x,""B""),1000000000, IF(REGEXMATCH(x,""M""),1000000, 1)), base * mult ), 0 )"),8.69E9) -> 8690000000 | D30: =IFERROR(__xludf.DUMMYFUNCTION("IFERROR( LET( x, UPPER(SUBSTITUTE(TRIM(Data!C95),CHAR(160),"""")), base, VALUE(SUBSTITUTE(REGEXEXTRACT(x,""[0-9.,]+""),"","","""")), mult, IF(REGEXMATCH(x,""B""),1000000000, IF(REGEXMATCH(x,""M""),1000000, 1)), base * mult ), 0 )"),1.15E10) -> 11500000000 | E30: =IFERROR(__xludf.DUMMYFUNCTION("IFERROR( LET( x, UPPER(SUBSTITUTE(TRIM(Data!D95),CHAR(160),"""")), base, VALUE(SUBSTITUTE(REGEXEXTRACT(x,""[0-9.,]+""),"","","""")), mult, IF(REGEXMATCH(x,""B""),1000000000, IF(REGEXMATCH(x,""M""),1000000, 1)), base * mult ), 0 )"),1.508E10) -> 15080000000 | F30: =IFERROR(__xludf.DUMMYFUNCTION("IFERROR( LET( x, UPPER(SUBSTITUTE(TRIM(Data!E95),CHAR(160),"""")), base, VALUE(SUBSTITUTE(REGEXEXTRACT(x,""[0-9.,]+""),"","","""")), mult, IF(REGEXMATCH(x,""B""),1000000000, IF(REGEXMATCH(x,""M""),1000000, 1)), base * mult ), 0 )"),1.89E10) -> 18900000000 | G30: =IFERROR(__xludf.DUMMYFUNCTION("IFERROR( LET( x, UPPER(SUBSTITUTE(TRIM(Data!F95),CHAR(160),"""")), base, VALUE(SUBSTITUTE(REGEXEXTRACT(x,""[0-9.,]+""),"","","""")), mult, IF(REGEXMATCH(x,""B""),1000000000, IF(REGEXMATCH(x,""M""),1000000, 1)), base * mult ), 0 )"),2.344E10) -> 23440000000 | H30: =AVERAGE(C30:G30) -> 15522000000 | I30: =AVERAGE(D30:H30) -> 16888400000 | J30: =AVERAGE(E30:I30) -> 17966080000 | K30: =AVERAGE(F30:J30) -> 18543296000 | L30: =AVERAGE(G30:K30) -> 18471955200
B31: Net Property, Plant & Equipment | C31: =IFERROR(__xludf.DUMMYFUNCTION("IFERROR( LET( x, UPPER(SUBSTITUTE(TRIM(Data!B89),CHAR(160),"""")), base, VALUE(SUBSTITUTE(REGEXEXTRACT(x,""[0-9.,]+""),"","","""")), mult, IF(REGEXMATCH(x,""B""),1000000000, IF(REGEXMATCH(x,""M""),1000000, 1)), base * mult ), 0 )"),3.118E10) -> 31180000000 | D31: =IFERROR(__xludf.DUMMYFUNCTION("IFERROR( LET( x, UPPER(SUBSTITUTE(TRIM(Data!C89),CHAR(160),"""")), base, VALUE(SUBSTITUTE(REGEXEXTRACT(x,""[0-9.,]+""),"","","""")), mult, IF(REGEXMATCH(x,""B""),1000000000, IF(REGEXMATCH(x,""M""),1000000, 1)), base * mult ), 0 )"),3.664E10) -> 36640000000 | E31: =IFERROR(__xludf.DUMMYFUNCTION("IFERROR( LET( x, UPPER(SUBSTITUTE(TRIM(Data!D89),CHAR(160),"""")), base, VALUE(SUBSTITUTE(REGEXEXTRACT(x,""[0-9.,]+""),"","","""")), mult, IF(REGEXMATCH(x,""B""),1000000000, IF(REGEXMATCH(x,""M""),1000000, 1)), base * mult ), 0 )"),4.512E10) -> 45120000000 | F31: =IFERROR(__xludf.DUMMYFUNCTION("IFERROR( LET( x, UPPER(SUBSTITUTE(TRIM(Data!E89),CHAR(160),"""")), base, VALUE(SUBSTITUTE(REGEXEXTRACT(x,""[0-9.,]+""),"","","""")), mult, IF(REGEXMATCH(x,""B""),1000000000, IF(REGEXMATCH(x,""M""),1000000, 1)), base * mult ), 0 )"),5.15E10) -> 51500000000 | G31: =IFERROR(__xludf.DUMMYFUNCTION("IFERROR( LET( x, UPPER(SUBSTITUTE(TRIM(Data!F89),CHAR(160),"""")), base, VALUE(SUBSTITUTE(REGEXEXTRACT(x,""[0-9.,]+""),"","","""")), mult, IF(REGEXMATCH(x,""B""),1000000000, IF(REGEXMATCH(x,""M""),1000000, 1)), base * mult ), 0 )"),5.619E10) -> 56190000000 | H31: =AVERAGE(C31:G31) -> 44126000000 | I31: =AVERAGE(D31:H31) -> 46715200000 | J31: =AVERAGE(E31:I31) -> 48730240000 | K31: =AVERAGE(F31:J31) -> 49452288000 | L31: =AVERAGE(G31:K31) -> 49042745600
B34: Intangible Assets | C34: =IFERROR(__xludf.DUMMYFUNCTION("IFERROR( LET( x, UPPER(SUBSTITUTE(TRIM(Data!B99),CHAR(160),"""")), base, VALUE(SUBSTITUTE(REGEXEXTRACT(x,""[0-9.,]+""),"","","""")), mult, IF(REGEXMATCH(x,""B""),1000000000, IF(REGEXMATCH(x,""M""),1000000, 1)), base * mult ), )"),1.72E9) -> 1720000000 | D34: =IFERROR(__xludf.DUMMYFUNCTION("IFERROR( LET( x, UPPER(SUBSTITUTE(TRIM(Data!C99),CHAR(160),"""")), base, VALUE(SUBSTITUTE(REGEXEXTRACT(x,""[0-9.,]+""),"","","""")), mult, IF(REGEXMATCH(x,""B""),1000000000, IF(REGEXMATCH(x,""M""),1000000, 1)), base * mult ), )"),5.93E8) -> 593000000 | E34: =IFERROR(__xludf.DUMMYFUNCTION("IFERROR( LET( x, UPPER(SUBSTITUTE(TRIM(Data!D99),CHAR(160),"""")), base, VALUE(SUBSTITUTE(REGEXEXTRACT(x,""[0-9.,]+""),"","","""")), mult, IF(REGEXMATCH(x,""B""),1000000000, IF(REGEXMATCH(x,""M""),1000000, 1)), base * mult ), )"),6.15E8) -> 615000000 | F34: =IFERROR(__xludf.DUMMYFUNCTION("IFERROR( LET( x, UPPER(SUBSTITUTE(TRIM(Data!E99),CHAR(160),"""")), base, VALUE(SUBSTITUTE(REGEXEXTRACT(x,""[0-9.,]+""),"","","""")), mult, IF(REGEXMATCH(x,""B""),1000000000, IF(REGEXMATCH(x,""M""),1000000, 1)), base * mult ), )"),1.47E9) -> 1470000000 | G34: =IFERROR(__xludf.DUMMYFUNCTION("IFERROR( LET( x, UPPER(SUBSTITUTE(TRIM(Data!B99),CHAR(160),"""")), base, VALUE(SUBSTITUTE(REGEXEXTRACT(x,""[0-9.,]+""),"","","""")), mult, IF(REGEXMATCH(x,""B""),1000000000, IF(REGEXMATCH(x,""M""),1000000, 1)), base * mult ), 0 )"),1.72E9) -> 1720000000 | H34: =FORECAST(H3,$C$34:G34,$C$3:G3) -> 1486700000 | I34: =FORECAST(I3,$C$34:H34,$C$3:H3) -> 1574400000 | J34: =FORECAST(J3,$C$34:I34,$C$3:I3) -> 1662100000 | K34: =FORECAST(K3,$C$34:J34,$C$3:J3) -> 1749800000 | L34: =FORECAST(L3,$C$34:K34,$C$3:K3) -> 1837500000
B35: Other Assets | C35: =IFERROR(__xludf.DUMMYFUNCTION("IFERROR( LET( x, UPPER(SUBSTITUTE(TRIM(Data!B102),CHAR(160),"""")), base, VALUE(SUBSTITUTE(REGEXEXTRACT(x,""[0-9.,]+""),"","","""")), mult, IF(REGEXMATCH(x,""B""),1000000000, IF(REGEXMATCH(x,""M""),1000000, 1)), base * mult ), 0 )"),1.62E9) -> 1620000000 | D35: =IFERROR(__xludf.DUMMYFUNCTION("IFERROR( LET( x, UPPER(SUBSTITUTE(TRIM(Data!C102),CHAR(160),"""")), base, VALUE(SUBSTITUTE(REGEXEXTRACT(x,""[0-9.,]+""),"","","""")), mult, IF(REGEXMATCH(x,""B""),1000000000, IF(REGEXMATCH(x,""M""),1000000, 1)), base * mult ), 0 )"),3.54E9) -> 3540000000 | E35: =IFERROR(__xludf.DUMMYFUNCTION("IFERROR( LET( x, UPPER(SUBSTITUTE(TRIM(Data!D102),CHAR(160),"""")), base, VALUE(SUBSTITUTE(REGEXEXTRACT(x,""[0-9.,]+""),"","","""")), mult, IF(REGEXMATCH(x,""B""),1000000000, IF(REGEXMATCH(x,""M""),1000000, 1)), base * mult ), 0 )"),4.0199999999999995E9) -> 4020000000 | F35: =IFERROR(__xludf.DUMMYFUNCTION("IFERROR( LET( x, UPPER(SUBSTITUTE(TRIM(Data!E102),CHAR(160),"""")), base, VALUE(SUBSTITUTE(REGEXEXTRACT(x,""[0-9.,]+""),"","","""")), mult, IF(REGEXMATCH(x,""B""),1000000000, IF(REGEXMATCH(x,""M""),1000000, 1)), base * mult ), 0 )"),3.56E9) -> 3560000000 | G35: =IFERROR(__xludf.DUMMYFUNCTION("IFERROR( LET( x, UPPER(SUBSTITUTE(TRIM(Data!F102),CHAR(160),"""")), base, VALUE(SUBSTITUTE(REGEXEXTRACT(x,""[0-9.,]+""),"","","""")), mult, IF(REGEXMATCH(x,""B""),1000000000, IF(REGEXMATCH(x,""M""),1000000, 1)), base * mult ), 0 )"),2.56E9) -> 2560000000 | H35: =FORECAST(H3,$C$35:G35,$C$3:G3) -> 3630000000 | I35: =FORECAST(I3,$C$35:H35,$C$3:H3) -> 3820000000 | J35: =FORECAST(J3,$C$35:I35,$C$3:I3) -> 4010000000 | K35: =FORECAST(K3,$C$35:J35,$C$3:J3) -> 4200000000 | L35: =FORECAST(L3,$C$35:K35,$C$3:K3) -> 4390000000
B36: Total Assets | C36: =IFERROR(__xludf.DUMMYFUNCTION("regexreplace(Data!B103,""B"","""")*1000000000"),6.213E10) -> 62130000000 | D36: =IFERROR(__xludf.DUMMYFUNCTION("regexreplace(Data!C103,""B"","""")*1000000000"),8.234E10) -> 82340000000 | E36: =IFERROR(__xludf.DUMMYFUNCTION("regexreplace(Data!D103,""B"","""")*1000000000"),1.0662E11) -> 106620000000 | F36: =IFERROR(__xludf.DUMMYFUNCTION("regexreplace(Data!E103,""B"","""")*1000000000"),1.2207E11) -> 122070000000 | G36: =IFERROR(__xludf.DUMMYFUNCTION("regexreplace(Data!F103,""B"","""")*1000000000"),1.3781E11) -> 137810000000 | H36: =G36*(1+H37) -> 168180476065 | I36: =H36*(1+I37) -> 205243977429 | J36: =I36*(1+J37) -> 250475508553 | K36: =J36*(1+K37) -> 305675134396 | L36: =K36*(1+L37) -> 373039617038
B37: Total Assets Growth | C37: - | D37: =Data!C104 -> 0.3252 | E37: =Data!D104 -> 0.2949 | F37: =Data!E104 -> 0.1449 | G37: =Data!F104 -> 0.1289 | H37: =(G36/C36)^(1/4)-1 -> 0.22037933 | I37: =H37 -> 0.22037933 | J37: =I37 -> 0.22037933 | K37: =J37 -> 0.22037933 | L37: =K37 -> 0.22037933
B40: Short Term Debt | C40: =IFERROR(__xludf.DUMMYFUNCTION("IFERROR( LET( x, UPPER(SUBSTITUTE(TRIM(Data!B334),CHAR(160),"""")), base, VALUE(SUBSTITUTE(REGEXEXTRACT(x,""[0-9.,]+""),"","","""")), mult, IF(REGEXMATCH(x,""B""),1000000000, IF(REGEXMATCH(x,""M""),1000000, 1)), base * mult ), 0 )"),3.68E8) -> 368000000 | D40: =IFERROR(__xludf.DUMMYFUNCTION("IFERROR( LET( x, UPPER(SUBSTITUTE(TRIM(Data!C334),CHAR(160),"""")), base, VALUE(SUBSTITUTE(REGEXEXTRACT(x,""[0-9.,]+""),"","","""")), mult, IF(REGEXMATCH(x,""B""),1000000000, IF(REGEXMATCH(x,""M""),1000000, 1)), base * mult ), 0 )"),4.85E8) -> 485000000 | E40: =IFERROR(__xludf.DUMMYFUNCTION("IFERROR( LET( x, UPPER(SUBSTITUTE(TRIM(Data!D334),CHAR(160),"""")), base, VALUE(SUBSTITUTE(REGEXEXTRACT(x,""[0-9.,]+""),"","","""")), mult, IF(REGEXMATCH(x,""B""),1000000000, IF(REGEXMATCH(x,""M""),1000000, 1)), base * mult ), 0 )"),6.72E8) -> 672000000 | F40: =IFERROR(__xludf.DUMMYFUNCTION("IFERROR( LET( x, UPPER(SUBSTITUTE(TRIM(Data!E334),CHAR(160),"""")), base, VALUE(SUBSTITUTE(REGEXEXTRACT(x,""[0-9.,]+""),"","","""")), mult, IF(REGEXMATCH(x,""B""),1000000000, IF(REGEXMATCH(x,""M""),1000000, 1)), base * mult ), 0 )"),8.07E8) -> 807000000 | G40: =IFERROR(__xludf.DUMMYFUNCTION("IFERROR( LET( x, UPPER(SUBSTITUTE(TRIM(Data!F334),CHAR(160),"""")), base, VALUE(SUBSTITUTE(REGEXEXTRACT(x,""[0-9.,]+""),"","","""")), mult, IF(REGEXMATCH(x,""B""),1000000000, IF(REGEXMATCH(x,""M""),1000000, 1)), base * mult ), 0 )"),9.54E8) -> 954000000 | H40: =FORECAST(H3,$C$40:G40,$C$3:G3) -> 1105400000 | I40: =FORECAST(I3,$C$40:H40,$C$3:H3) -> 1254800000 | J40: =FORECAST(J3,$C$40:I40,$C$3:I3) -> 1404200000 | K40: =FORECAST(K3,$C$40:J40,$C$3:J3) -> 1553600000 | L40: =FORECAST(L3,$C$40:K40,$C$3:K3) -> 1703000000
B41: Current Portion of Long Term Debt | C41: =IFERROR(__xludf.DUMMYFUNCTION("IFERROR( LET( x, UPPER(SUBSTITUTE(TRIM(Data!B335),CHAR(160),"""")), base, VALUE(SUBSTITUTE(REGEXEXTRACT(x,""[0-9.,]+""),"","","""")), mult, IF(REGEXMATCH(x,""B""),1000000000, IF(REGEXMATCH(x,""M""),1000000, 1)), base * mult ), 0 )"),1.59E9) -> 1590000000 | D41: =IFERROR(__xludf.DUMMYFUNCTION("IFERROR( LET( x, UPPER(SUBSTITUTE(TRIM(Data!C335),CHAR(160),"""")), base, VALUE(SUBSTITUTE(REGEXEXTRACT(x,""[0-9.,]+""),"","","""")), mult, IF(REGEXMATCH(x,""B""),1000000000, IF(REGEXMATCH(x,""M""),1000000, 1)), base * mult ), 0 )"),1.5E9) -> 1500000000 | E41: =IFERROR(__xludf.DUMMYFUNCTION("IFERROR( LET( x, UPPER(SUBSTITUTE(TRIM(Data!D335),CHAR(160),"""")), base, VALUE(SUBSTITUTE(REGEXEXTRACT(x,""[0-9.,]+""),"","","""")), mult, IF(REGEXMATCH(x,""B""),1000000000, IF(REGEXMATCH(x,""M""),1000000, 1)), base * mult ), 0 )"),2.37E9) -> 2370000000 | F41: =IFERROR(__xludf.DUMMYFUNCTION("IFERROR( LET( x, UPPER(SUBSTITUTE(TRIM(Data!E335),CHAR(160),"""")), base, VALUE(SUBSTITUTE(REGEXEXTRACT(x,""[0-9.,]+""),"","","""")), mult, IF(REGEXMATCH(x,""B""),1000000000, IF(REGEXMATCH(x,""M""),1000000, 1)), base * mult ), 0 )"),2.46E9) -> 2460000000 | G41: =IFERROR(__xludf.DUMMYFUNCTION("IFERROR( LET( x, UPPER(SUBSTITUTE(TRIM(Data!F335),CHAR(160),"""")), base, VALUE(SUBSTITUTE(REGEXEXTRACT(x,""[0-9.,]+""),"","","""")), mult, IF(REGEXMATCH(x,""B""),1000000000, IF(REGEXMATCH(x,""M""),1000000, 1)), base * mult ), 0 )"),1.64E9) -> 1640000000 | H41: =AVERAGE(C41:G41) -> 1912000000 | I41: =AVERAGE(D41:H41) -> 1976400000 | J41: =AVERAGE(E41:I41) -> 2071680000 | K41: =AVERAGE(F41:J41) -> 2012016000 | L41: =AVERAGE(G41:K41) -> 1922419200
B42: ST Debt & Current Portion LT Debt | C42: =IFERROR(__xludf.DUMMYFUNCTION("IFERROR( LET( x, UPPER(SUBSTITUTE(TRIM(Data!B333),CHAR(160),"""")), base, VALUE(SUBSTITUTE(REGEXEXTRACT(x,""[0-9.,]+""),"","","""")), mult, IF(REGEXMATCH(x,""B""),1000000000, IF(REGEXMATCH(x,""M""),1000000, 1)), base * mult ), 0 )"),1.96E9) -> 1960000000 | D42: =IFERROR(__xludf.DUMMYFUNCTION("IFERROR( LET( x, UPPER(SUBSTITUTE(TRIM(Data!C333),CHAR(160),"""")), base, VALUE(SUBSTITUTE(REGEXEXTRACT(x,""[0-9.,]+""),"","","""")), mult, IF(REGEXMATCH(x,""B""),1000000000, IF(REGEXMATCH(x,""M""),1000000, 1)), base * mult ), 0 )"),1.99E9) -> 1990000000 | E42: =IFERROR(__xludf.DUMMYFUNCTION("IFERROR( LET( x, UPPER(SUBSTITUTE(TRIM(Data!D333),CHAR(160),"""")), base, VALUE(SUBSTITUTE(REGEXEXTRACT(x,""[0-9.,]+""),"","","""")), mult, IF(REGEXMATCH(x,""B""),1000000000, IF(REGEXMATCH(x,""M""),1000000, 1)), base * mult ), 0 )"),3.05E9) -> 3050000000 | F42: =IFERROR(__xludf.DUMMYFUNCTION("IFERROR( LET( x, UPPER(SUBSTITUTE(TRIM(Data!E333),CHAR(160),"""")), base, VALUE(SUBSTITUTE(REGEXEXTRACT(x,""[0-9.,]+""),"","","""")), mult, IF(REGEXMATCH(x,""B""),1000000000, IF(REGEXMATCH(x,""M""),1000000, 1)), base * mult ), 0 )"),3.26E9) -> 3260000000 | G42: =IFERROR(__xludf.DUMMYFUNCTION("IFERROR( LET( x, UPPER(SUBSTITUTE(TRIM(Data!F333),CHAR(160),"""")), base, VALUE(SUBSTITUTE(REGEXEXTRACT(x,""[0-9.,]+""),"","","""")), mult, IF(REGEXMATCH(x,""B""),1000000000, IF(REGEXMATCH(x,""M""),1000000, 1)), base * mult ), 0 )"),2.59E9) -> 2590000000 | H42: =FORECAST(H3,$C$42:G42,$C$3:G3) -> 3329000000 | I42: =FORECAST(I3,$C$42:H42,$C$3:H3) -> 3582000000 | J42: =FORECAST(J3,$C$42:I42,$C$3:I3) -> 3835000000 | K42: =FORECAST(K3,$C$42:J42,$C$3:J3) -> 4088000000 | L42: =FORECAST(L3,$C$42:K42,$C$3:K3) -> 4341000000

Sheet Cash Flow
B2: Balance Sheet | C2: FY | H2: Future FY
C3: 2020 | D3: 2021 | E3: 2022 | F3: 2023 | G3: 2024 | H3: 2025 | I3: 2026 | J3: 2027 | K3: 2028 | L3: 2029
B6: Net Income before Extraordinaries | C6: =IFERROR(__xludf.DUMMYFUNCTION("IFERROR( LET( x, UPPER(SUBSTITUTE(TRIM(Data!B112),CHAR(160),"""")), base, VALUE(SUBSTITUTE(REGEXEXTRACT(x,""[0-9.,]+""),"","","""")), mult, IF(REGEXMATCH(x,""B""),1000000000, IF(REGEXMATCH(x,""M""),1000000, 1)), base * mult ), 0 ) "),5.64E9) -> 5640000000 | D6: =IFERROR(__xludf.DUMMYFUNCTION("IFERROR( LET( x, UPPER(SUBSTITUTE(TRIM(Data!C112),CHAR(160),"""")), base, VALUE(SUBSTITUTE(REGEXEXTRACT(x,""[0-9.,]+""),"","","""")), mult, IF(REGEXMATCH(x,""B""),1000000000, IF(REGEXMATCH(x,""M""),1000000, 1)), base * mult ), )"),1.259E10) -> 12590000000 | E6: =IFERROR(__xludf.DUMMYFUNCTION("IFERROR( LET( x, UPPER(SUBSTITUTE(TRIM(Data!D112),CHAR(160),"""")), base, VALUE(SUBSTITUTE(REGEXEXTRACT(x,""[0-9.,]+""),"","","""")), mult, IF(REGEXMATCH(x,""B""),1000000000, IF(REGEXMATCH(x,""M""),1000000, 1)), base * mult ), )"),1.497E10) -> 14970000000 | F6: =IFERROR(__xludf.DUMMYFUNCTION("IFERROR( LET( x, UPPER(SUBSTITUTE(TRIM(Data!E112),CHAR(160),"""")), base, VALUE(SUBSTITUTE(REGEXEXTRACT(x,""[0-9.,]+""),"","","""")), mult, IF(REGEXMATCH(x,""B""),1000000000, IF(REGEXMATCH(x,""M""),1000000, 1)), base * mult ), )"),7.15E9) -> 7150000000 | G6: =IFERROR(__xludf.DUMMYFUNCTION("IFERROR( LET( x, UPPER(SUBSTITUTE(TRIM(Data!F112),CHAR(160),"""")), base, VALUE(SUBSTITUTE(REGEXEXTRACT(x,""[0-9.,]+""),"","","""")), mult, IF(REGEXMATCH(x,""B""),1000000000, IF(REGEXMATCH(x,""M""),1000000, 1)), base * mult ), )"),3.86E9) -> 3860000000 | H6: =FORECAST(H3,$C$6:G6,$C$3:G3) -> 6142000000 | I6: =FORECAST(I3,$C$6:H6,$C$3:H3) -> 5242000000 | J6: =FORECAST(J3,$C$6:I6,$C$3:I3) -> 4342000000 | K6: =FORECAST(K3,$C$6:J6,$C$3:J3) -> 3442000000 | L6: =FORECAST(L3,$C$6:K6,$C$3:K3) -> 2542000000
B7: Net Income Growth | C7: =Data!B113 -> - | D7: =Data!C113 -> 1.2302 | E7: =Data!D113 -> 0.1896 | F7: =Data!E113 -> -0.5223 | G7: =Data!F113 -> -0.4611 | H7: =H6/G6-1 -> 0.59119171 | I7: =I6/H6-1 -> -0.14653207 | J7: =J6/I6-1 -> -0.17169019 | K7: =K6/J6-1 -> -0.20727775 | L7: =L6/K6-1 -> -0.26147589
B10: Depreciation, Depletion & Amortization | C10: =IFERROR(__xludf.DUMMYFUNCTION("IFERROR( LET( x, UPPER(SUBSTITUTE(TRIM(Data!B114),CHAR(160),"""")), base, VALUE(SUBSTITUTE(REGEXEXTRACT(x,""[0-9.,]+""),"","","""")), mult, IF(REGEXMATCH(x,""B""),1000000000, IF(REGEXMATCH(x,""M""),1000000, 1)), base * mult ), 0 ) "),2.91E9) -> 2910000000 | D10: =IFERROR(__xludf.DUMMYFUNCTION("IFERROR( LET( x, UPPER(SUBSTITUTE(TRIM(Data!C114),CHAR(160),"""")), base, VALUE(SUBSTITUTE(REGEXEXTRACT(x,""[0-9.,]+""),"","","""")), mult, IF(REGEXMATCH(x,""B""),1000000000, IF(REGEXMATCH(x,""M""),1000000, 1)), base * mult ), 0 ) "),3.75E9) -> 3750000000 | E10: =IFERROR(__xludf.DUMMYFUNCTION("IFERROR( LET( x, UPPER(SUBSTITUTE(TRIM(Data!D114),CHAR(160),"""")), base, VALUE(SUBSTITUTE(REGEXEXTRACT(x,""[0-9.,]+""),"","","""")), mult, IF(REGEXMATCH(x,""B""),1000000000, IF(REGEXMATCH(x,""M""),1000000, 1)), base * mult ), 0 ) "),4.67E9) -> 4670000000 | F10: =IFERROR(__xludf.DUMMYFUNCTION("IFERROR( LET( x, UPPER(SUBSTITUTE(TRIM(Data!E114),CHAR(160),"""")), base, VALUE(SUBSTITUTE(REGEXEXTRACT(x,""[0-9.,]+""),"","","""")), mult, IF(REGEXMATCH(x,""B""),1000000000, IF(REGEXMATCH(x,""M""),1000000, 1)), base * mult ), 0 ) "),5.37E9) -> 5370000000 | G10: =IFERROR(__xludf.DUMMYFUNCTION("IFERROR( LET( x, UPPER(SUBSTITUTE(TRIM(Data!F114),CHAR(160),"""")), base, VALUE(SUBSTITUTE(REGEXEXTRACT(x,""[0-9.,]+""),"","","""")), mult, IF(REGEXMATCH(x,""B""),1000000000, IF(REGEXMATCH(x,""M""),1000000, 1)), base * mult ), 0 ) "),6.15E9) -> 6150000000 | H10: =FORECAST(H3,$C$10:G10,$C$3:G3) -> 7000000000 | I10: =FORECAST(I3,$C$10:H10,$C$3:H3) -> 7810000000 | J10: =FORECAST(J3,$C$10:I10,$C$3:I3) -> 8620000000 | K10: =FORECAST(K3,$C$10:J10,$C$3:J3) -> 9430000000 | L10: =FORECAST(L3,$C$10:K10,$C$3:K3) -> 10240000000
B13: Net Operating Cash Flow | C13: =IFERROR(__xludf.DUMMYFUNCTION("IFERROR( LET( x, UPPER(SUBSTITUTE(TRIM(Data!B127),CHAR(160),"""")), base, VALUE(SUBSTITUTE(REGEXEXTRACT(x,""[0-9.,]+""),"","","""")), mult, IF(REGEXMATCH(x,""B""),1000000000, IF(REGEXMATCH(x,""M""),1000000, 1)), base * mult ), 0 ) "),1.15E10) -> 11500000000 | D13: =IFERROR(__xludf.DUMMYFUNCTION("IFERROR( LET( x, UPPER(SUBSTITUTE(TRIM(Data!C127),CHAR(160),"""")), base, VALUE(SUBSTITUTE(REGEXEXTRACT(x,""[0-9.,]+""),"","","""")), mult, IF(REGEXMATCH(x,""B""),1000000000, IF(REGEXMATCH(x,""M""),1000000, 1)), base * mult ), 0 ) "),1.472E10) -> 14720000000 | E13: =IFERROR(__xludf.DUMMYFUNCTION("IFERROR( LET( x, UPPER(SUBSTITUTE(TRIM(Data!D127),CHAR(160),"""")), base, VALUE(SUBSTITUTE(REGEXEXTRACT(x,""[0-9.,]+""),"","","""")), mult, IF(REGEXMATCH(x,""B""),1000000000, IF(REGEXMATCH(x,""M""),1000000, 1)), base * mult ), 0 ) "),1.326E10) -> 13260000000 | F13: =IFERROR(__xludf.DUMMYFUNCTION("IFERROR( LET( x, UPPER(SUBSTITUTE(TRIM(Data!E127),CHAR(160),"""")), base, VALUE(SUBSTITUTE(REGEXEXTRACT(x,""[0-9.,]+""),"","","""")), mult, IF(REGEXMATCH(x,""B""),1000000000, IF(REGEXMATCH(x,""M""),1000000, 1)), base * mult ), 0 ) "),1.492E10) -> 14920000000 | G13: =IFERROR(__xludf.DUMMYFUNCTION("IFERROR( LET( x, UPPER(SUBSTITUTE(TRIM(Data!F127),CHAR(160),"""")), base, VALUE(SUBSTITUTE(REGEXEXTRACT(x,""[0-9.,]+""),"","","""")), mult, IF(REGEXMATCH(x,""B""),1000000000, IF(REGEXMATCH(x,""M""),1000000, 1)), base * mult ), 0 ) "),1.475E10) -> 14750000000 | H13: =FORECAST(H3,$C$13:G13,$C$3:G3) -> 15840000000 | I13: =FORECAST(I3,$C$13:H13,$C$3:H3) -> 16510000000 | J13: =FORECAST(J3,$C$13:I13,$C$3:I3) -> 17180000000 | K13: =FORECAST(K3,$C$13:J13,$C$3:J3) -> 17850000000 | L13: =FORECAST(L3,$C$13:K13,$C$3:K3) -> 18520000000
B14: Net Operating Cash Flow Growth | C14: =Data!B128 -> - | D14: =Data!C128 -> 0.2807 | E14: =Data!D128 -> -0.0997 | F14: =Data!E128 -> 0.1258 | G14: =Data!F128 -> -0.0118 | H14: =H13/G13-1 -> 0.073898305 | I14: =I13/H13-1 -> 0.04229798 | J14: =J13/I13-1 -> 0.040581466 | K14: =K13/J13-1 -> 0.038998836 | L14: =L13/K13-1 -> 0.037535014
B17: Net Change in Cash | C17: =IFERROR(__xludf.DUMMYFUNCTION("IFERROR( LET( x, UPPER(SUBSTITUTE(TRIM(Data!B153),CHAR(160),"""")), base, VALUE(SUBSTITUTE(REGEXEXTRACT(x,""[0-9.,]+""),"","","""")), mult, IF(REGEXMATCH(x,""B""),1000000000, IF(REGEXMATCH(x,""M""),1000000, 1)), base * mult ), 0 ) "),1.76E9) -> 1760000000 | D17: =IFERROR(__xludf.DUMMYFUNCTION("IFERROR( LET( x, UPPER(SUBSTITUTE(TRIM(Data!C153),CHAR(160),"""")), base, VALUE(SUBSTITUTE(REGEXEXTRACT(x,""[0-9.,]+""),"","","""")), mult, IF(REGEXMATCH(x,""B""),1000000000, IF(REGEXMATCH(x,""M""),1000000, 1)), base * mult ), 0 ) "),1.22E9) -> 1220000000 | E17: =IFERROR(__xludf.DUMMYFUNCTION("IFERROR( LET( x, UPPER(SUBSTITUTE(TRIM(Data!D153),CHAR(160),"""")), base, VALUE(SUBSTITUTE(REGEXEXTRACT(x,""[0-9.,]+""),"","","""")), mult, IF(REGEXMATCH(x,""B""),1000000000, IF(REGEXMATCH(x,""M""),1000000, 1)), base * mult ), 0 ) "),2.65E8) -> 265000000 | F17: =IFERROR(__xludf.DUMMYFUNCTION("IFERROR( LET( x, UPPER(SUBSTITUTE(TRIM(Data!E153),CHAR(160),"""")), base, VALUE(SUBSTITUTE(REGEXEXTRACT(x,""[0-9.,]+""),"","","""")), mult, IF(REGEXMATCH(x,""B""),1000000000, IF(REGEXMATCH(x,""M""),1000000, 1)), base * mult ), 0 ) "),1.52E8) -> 152000000 | G17: =IFERROR(__xludf.DUMMYFUNCTION("IFERROR( LET( x, UPPER(SUBSTITUTE(TRIM(Data!F153),CHAR(160),"""")), base, VALUE(SUBSTITUTE(REGEXEXTRACT(x,""[0-9.,]+""),"","","""")), mult, IF(REGEXMATCH(x,""B""),1000000000, IF(REGEXMATCH(x,""M""),1000000, 1)), base * mult ), 0 ) "),5.79E8) -> 579000000 | H17: =AVERAGEIF(C17:G17,">0.5") -> 795200000 | I17: =AVERAGEIF(D17:H17,">0.5") -> 602240000 | J17: =AVERAGEIF(E17:I17,">0.5") -> 478688000 | K17: =AVERAGEIF(F17:J17,">0.5") -> 521425600 | L17: =AVERAGEIF(G17:K17,">0.5") -> 595310720
B18: Free Cash Flow | C18: =IFERROR(__xludf.DUMMYFUNCTION("IFERROR( LET( x, UPPER(SUBSTITUTE(TRIM(Data!B154),CHAR(160),"""")), base, VALUE(SUBSTITUTE(REGEXEXTRACT(x,""[0-9.,]+""),"","","""")), mult, IF(REGEXMATCH(x,""B""),1000000000, IF(REGEXMATCH(x,""M""),1000000, 1)), base * mult ), 0 ) "),4.98E9) -> 4980000000 | D18: =IFERROR(__xludf.DUMMYFUNCTION("IFERROR( LET( x, UPPER(SUBSTITUTE(TRIM(Data!C154),CHAR(160),"""")), base, VALUE(SUBSTITUTE(REGEXEXTRACT(x,""[0-9.,]+""),"","","""")), mult, IF(REGEXMATCH(x,""B""),1000000000, IF(REGEXMATCH(x,""M""),1000000, 1)), base * mult ), 0 ) "),7.56E9) -> 7560000000 | E18: =IFERROR(__xludf.DUMMYFUNCTION("IFERROR( LET( x, UPPER(SUBSTITUTE(TRIM(Data!D154),CHAR(160),"""")), base, VALUE(SUBSTITUTE(REGEXEXTRACT(x,""[0-9.,]+""),"","","""")), mult, IF(REGEXMATCH(x,""B""),1000000000, IF(REGEXMATCH(x,""M""),1000000, 1)), base * mult ), 0 ) "),4.36E9) -> 4360000000 | F18: =IFERROR(__xludf.DUMMYFUNCTION("IFERROR( LET( x, UPPER(SUBSTITUTE(TRIM(Data!E154),CHAR(160),"""")), base, VALUE(SUBSTITUTE(REGEXEXTRACT(x,""[0-9.,]+""),"","","""")), mult, IF(REGEXMATCH(x,""B""),1000000000, IF(REGEXMATCH(x,""M""),1000000, 1)), base * mult ), 0 ) "),3.58E9) -> 3580000000 | G18: =IFERROR(__xludf.DUMMYFUNCTION("IFERROR( LET( x, UPPER(SUBSTITUTE(TRIM(Data!F154),CHAR(160),"""")), base, VALUE(SUBSTITUTE(REGEXEXTRACT(x,""[0-9.,]+""),"","","""")), mult, IF(REGEXMATCH(x,""B""),1000000000, IF(REGEXMATCH(x,""M""),1000000, 1)), base * mult ), 0 ) "),6.22E9) -> 6220000000 | H18: =G18*(1+H19) -> 6575528208 | I18: =H18*(1+I19) -> 6754112163 | J18: =I18*(1+J19) -> 6734922892 | K18: =J18*(1+K19) -> 6513740454 | L18: =K18*(1+L19) -> 6104409681
B19: Free Cash Flow Growth | C19: =Data!B155 -> - | D19: =Data!C155 -> 0.5174 | E19: =Data!D155 -> -0.4238 | F19: =Data!E155 -> -0.1781 | G19: =Data!F155 -> 0.7369 | H19: =(G18/C18)^(1/4)-1 -> 0.057158876 | I19: =H19-3% -> 0.027158876 | J19: =I19-3% -> -0.0028411241 | K19: =J19-3% -> -0.032841124 | L19: =K19-3% -> -0.062841124

Sheet DCF
G2: TradingView Revenue Estimates
B4: Discounted Cash Flow | C4: FY | H4: Future FY
C5: 2020 | D5: 2021 | E5: 2022 | F5: 2023 | G5: 2024 | H5: 2025 | I5: 2026 | J5: 2027 | K5: 2028
B8: Revenue | C8: ='Income Statement'!C15 -> 53820000000 | D8: ='Income Statement'!D15 -> 81460000000 | E8: ='Income Statement'!E15 -> 96770000000 | F8: ='Income Statement'!F15 -> 97690000000 | G8: ='Income Statement'!G15 -> 94830000000 | H8: 102430000000 | I8: 117900000000 | J8: 139270000000 | K8: 220000000000
B9: % growth | C9: - | D9: =D8/C8-1 -> 0.51356373 | E9: =E8/D8-1 -> 0.187945 | F9: =F8/E8-1 -> 0.0095070786 | G9: =G8/F8-1 -> -0.029276282 | H9: =H8/G8-1 -> 0.080143415 | I9: =I8/H8-1 -> 0.15102997 | J9: =J8/I8-1 -> 0.1812553 | K9: =K8/J8-1 -> 0.5796654
B12: EBIT | C12: =IFERROR(__xludf.DUMMYFUNCTION("IFERROR( LET( x, UPPER(SUBSTITUTE(TRIM(Data!B22),CHAR(160),"""")), neg, IF(LEFT(x,1)=""("", -1, 1), numtext, REGEXEXTRACT(x,""[0-9.,]+""), base, VALUE(SUBSTITUTE(numtext,"","","""")), mult, IF(REGEXMATCH(x,""B""),1000000000, IF(REGEX"&"MATCH(x,""M""),1000000, 1)), neg * base * mult ), 0 ) "),6.54E9) -> 6540000000 | D12: =IFERROR(__xludf.DUMMYFUNCTION("IFERROR( LET( x, UPPER(SUBSTITUTE(TRIM(Data!C22),CHAR(160),"""")), neg, IF(LEFT(x,1)=""("", -1, 1), numtext, REGEXEXTRACT(x,""[0-9.,]+""), base, VALUE(SUBSTITUTE(numtext,"","","""")), mult, IF(REGEXMATCH(x,""B""),1000000000, IF(REGEX"&"MATCH(x,""M""),1000000, 1)), neg * base * mult ), 0 ) "),1.368E10) -> 13680000000 | E12: =IFERROR(__xludf.DUMMYFUNCTION("IFERROR( LET( x, UPPER(SUBSTITUTE(TRIM(Data!D22),CHAR(160),"""")), neg, IF(LEFT(x,1)=""("", -1, 1), numtext, REGEXEXTRACT(x,""[0-9.,]+""), base, VALUE(SUBSTITUTE(numtext,"","","""")), mult, IF(REGEXMATCH(x,""B""),1000000000, IF(REGEX"&"MATCH(x,""M""),1000000, 1)), neg * base * mult ), 0 ) "),8.89E9) -> 8890000000 | F12: =IFERROR(__xludf.DUMMYFUNCTION("IFERROR( LET( x, UPPER(SUBSTITUTE(TRIM(Data!E22),CHAR(160),"""")), neg, IF(LEFT(x,1)=""("", -1, 1), numtext, REGEXEXTRACT(x,""[0-9.,]+""), base, VALUE(SUBSTITUTE(numtext,"","","""")), mult, IF(REGEXMATCH(x,""B""),1000000000, IF(REGEX"&"MATCH(x,""M""),1000000, 1)), neg * base * mult ), 0 ) "),7.09E9) -> 7090000000 | G12: =IFERROR(__xludf.DUMMYFUNCTION("IFERROR( LET( x, UPPER(SUBSTITUTE(TRIM(Data!F22),CHAR(160),"""")), neg, IF(LEFT(x,1)=""("", -1, 1), numtext, REGEXEXTRACT(x,""[0-9.,]+""), base, VALUE(SUBSTITUTE(numtext,"","","""")), mult, IF(REGEXMATCH(x,""B""),1000000000, IF(REGEX"&"MATCH(x,""M""),1000000, 1)), neg * base * mult ), 0 ) "),4.29E9) -> 4290000000 | H12: =H8*H13 -> 7159265647 | I12: =I8*I13 -> 8240529335 | J12: =J8*J13 -> 9734168960 | K12: =K8*K13 -> 15376729887
