Workbook

Sheet Income Statement
C1: Ticker Name: | D1: mrk
C3: Current Price | D3: =IFERROR(__xludf.DUMMYFUNCTION("GOOGLEFINANCE(D1,""PRICE"")"),125.37) -> 125.37 | E3: %-change from implied | F3: =D4/D3-1 -> 0.19622026
C4: Implied Share Value | D4: =DCF!C85 -> 149.97013 | E4: %-change (1 month) | F4: =IFERROR(__xludf.DUMMYFUNCTION("(D3-INDEX(GOOGLEFINANCE(D1,""price"",EDATE(TODAY(),-1)),2,2))/D3"),0.0813591768365638) -> 0.081359177
C6: Chart (1 years) | D6: =IFERROR(__xludf.DUMMYFUNCTION("SPARKLINE(INDEX(GOOGLEFINANCE(D1,""price"",EDATE(today(),-12),today()), ,2),{""charttype"",""column"";""color"",""red""})"),"") | E6: %-change (6 months) | F6: =IFERROR(__xludf.DUMMYFUNCTION("(D3-INDEX(GOOGLEFINANCE(D1,""price"",EDATE(TODAY(),-6)),2,2))/D3"),0.15091329664193986) -> 0.1509133
C8: Chart (5 years) | D8: =IFERROR(__xludf.DUMMYFUNCTION("SPARKLINE(INDEX(GOOGLEFINANCE(D1,""price"",EDATE(today(),-60),today()), ,2),{""charttype"",""column"";""color"",""red""})"),"") | E8: %-change (12 months) | F8: =IFERROR(__xludf.DUMMYFUNCTION("(D3-INDEX(GOOGLEFINANCE(D1,""price"",EDATE(TODAY(),-12)),2,2))/D3"),0.3474515434314429) -> 0.34745154
B11: Income Statement | C11: FY | H11: Future FY
C12: 2020 | D12: 2021 | E12: 2022 | F12: 2023 | G12: 2024 | H12: 2025 | I12: 2026 | J12: 2027 | K12: 2028 | L12: 2029
B15: Revenue | C15: =IFERROR(__xludf.DUMMYFUNCTION("IFERROR( LET( x, UPPER(SUBSTITUTE(TRIM(Data!B5),CHAR(160),"""")), base, VALUE(SUBSTITUTE(REGEXEXTRACT(x,""[0-9.,]+""),"","","""")), mult, IF(REGEXMATCH(x,""B""),1000000000, IF(REGEXMATCH(x,""M""),1000000, 1)), base * mult ), 0 )"),4.891E10) -> 48910000000 | D15: =IFERROR(__xludf.DUMMYFUNCTION("IFERROR( LET( x, UPPER(SUBSTITUTE(TRIM(Data!C5),CHAR(160),"""")), base, VALUE(SUBSTITUTE(REGEXEXTRACT(x,""[0-9.,]+""),"","","""")), mult, IF(REGEXMATCH(x,""B""),1000000000, IF(REGEXMATCH(x,""M""),1000000, 1)), base * mult ), 0 )"),5.847E10) -> 58470000000 | E15: =IFERROR(__xludf.DUMMYFUNCTION("IFERROR( LET( x, UPPER(SUBSTITUTE(TRIM(Data!D5),CHAR(160),"""")), base, VALUE(SUBSTITUTE(REGEXEXTRACT(x,""[0-9.,]+""),"","","""")), mult, IF(REGEXMATCH(x,""B""),1000000000, IF(REGEXMATCH(x,""M""),1000000, 1)), base * mult ), 0 )"),5.987E10) -> 59870000000 | F15: =IFERROR(__xludf.DUMMYFUNCTION("IFERROR( LET( x, UPPER(SUBSTITUTE(TRIM(Data!E5),CHAR(160),"""")), base, VALUE(SUBSTITUTE(REGEXEXTRACT(x,""[0-9.,]+""),"","","""")), mult, IF(REGEXMATCH(x,""B""),1000000000, IF(REGEXMATCH(x,""M""),1000000, 1)), base * mult ), 0 )"),6.397E10) -> 63970000000 | G15: =IFERROR(__xludf.DUMMYFUNCTION("IFERROR( LET( x, UPPER(SUBSTITUTE(TRIM(Data!F5),CHAR(160),"""")), base, VALUE(SUBSTITUTE(REGEXEXTRACT(x,""[0-9.,]+""),"","","""")), mult, IF(REGEXMATCH(x,""B""),1000000000, IF(REGEXMATCH(x,""M""),1000000, 1)), base * mult ), 0 )"),6.493000000000001E10) -> 64930000000 | H15: =DCF!H8 -> 66680000000 | I15: =H15*(1+H16) -> 71574368703 | J15: =I15*(1+I16) -> 76827988232 | K15: =J15*(1+J16) -> 82467227901 | L15: =K15*(1+K16) -> 88520392558
B16: Revenue Growth | C16: =Data!B6 -> - | D16: =Data!C6 -> 0.1956 | E16: =Data!D6 -> 0.0239 | F16: =Data!E6 -> 0.0685 | G16: =Data!F6 -> 0.0149 | H16: =(G15/C15)^(1/4)-1 -> 0.07340085 | I16: =H16 -> 0.07340085 | J16: =I16 -> 0.07340085 | K16: =J16 -> 0.07340085 | L16: =K16 -> 0.07340085
B18: Cost of Sales | C18: =Data!B7 -> 13.47B | D18: =Data!C7 -> 17.21B | E18: =Data!D7 -> 15.98B | F18: =Data!E7 -> 16.8B | G18: =Data!F7 -> 18.2B | H18: =H15-H19 -> 16604960796 | I18: =I15-I19 -> 17914844816 | J18: =J15-J19 -> 19327394131 | K18: =K15-K19 -> 20850611084 | L18: =L15-L19 -> 22493118799
B19: Gross Profit | C19: =Data!B13 -> 35.44B | D19: =Data!C13 -> 41.27B | E19: =Data!D13 -> 43.89B | F19: =Data!E13 -> 47.17B | G19: =Data!F13 -> 46.73B | H19: =IFERROR(__xludf.DUMMYFUNCTION("REGEXREPLACE(G19,""B"","""")*1000000000*(1+H20)"),5.007503920394899E10) -> 50075039204 | I19: =H19*(1+I20) -> 53659523888 | J19: =I19*(1+J20) -> 57500594101 | K19: =J19*(1+K20) -> 61616616817 | L19: =K19*(1+L20) -> 66027273758
B20: Gross Profit Growth | C20: =Data!B14 -> - | D20: =Data!C14 -> 0.1644 | E20: =Data!D14 -> 0.0637 | F20: =Data!E14 -> 0.0747 | G20: =Data!F14 -> -0.0093 | H20: =IFERROR(__xludf.DUMMYFUNCTION("(REGEXREPLACE(G19,""B"","""")/REGEXREPLACE(C19,""B"",""""))^(1/4)-1"),0.07158226415469704) -> 0.071582264 | I20: =H20 -> 0.071582264 | J20: =I20 -> 0.071582264 | K20: =J20 -> 0.071582264 | L20: =K20 -> 0.071582264
B23: Selling, General & Admin | C23: =IFERROR(__xludf.DUMMYFUNCTION("IFERROR( LET( x, UPPER(SUBSTITUTE(TRIM(Data!B16),CHAR(160),"""")), base, VALUE(SUBSTITUTE(REGEXEXTRACT(x,""[0-9.,]+""),"","","""")), mult, IF(REGEXMATCH(x,""B""),1000000000, IF(REGEXMATCH(x,""M""),1000000, 1)), base * mult ), 0 )"),1.982E10) -> 19820000000 | D23: =IFERROR(__xludf.DUMMYFUNCTION("IFERROR( LET( x, UPPER(SUBSTITUTE(TRIM(Data!C16),CHAR(160),"""")), base, VALUE(SUBSTITUTE(REGEXEXTRACT(x,""[0-9.,]+""),"","","""")), mult, IF(REGEXMATCH(x,""B""),1000000000, IF(REGEXMATCH(x,""M""),1000000, 1)), base * mult ), 0 )"),2.177E10) -> 21770000000 | E23: =IFERROR(__xludf.DUMMYFUNCTION("IFERROR( LET( x, UPPER(SUBSTITUTE(TRIM(Data!D16),CHAR(160),"""")), base, VALUE(SUBSTITUTE(REGEXEXTRACT(x,""[0-9.,]+""),"","","""")), mult, IF(REGEXMATCH(x,""B""),1000000000, IF(REGEXMATCH(x,""M""),1000000, 1)), base * mult ), 0 )"),4.091E10) -> 40910000000 | F23: =IFERROR(__xludf.DUMMYFUNCTION("IFERROR( LET( x, UPPER(SUBSTITUTE(TRIM(Data!E16),CHAR(160),"""")), base, VALUE(SUBSTITUTE(REGEXEXTRACT(x,""[0-9.,]+""),"","","""")), mult, IF(REGEXMATCH(x,""B""),1000000000, IF(REGEXMATCH(x,""M""),1000000, 1)), base * mult ), 0 )"),2.653E10) -> 26530000000 | G23: =IFERROR(__xludf.DUMMYFUNCTION("IFERROR( LET( x, UPPER(SUBSTITUTE(TRIM(Data!F16),CHAR(160),"""")), base, VALUE(SUBSTITUTE(REGEXEXTRACT(x,""[0-9.,]+""),"","","""")), mult, IF(REGEXMATCH(x,""B""),1000000000, IF(REGEXMATCH(x,""M""),1000000, 1)), base * mult ), 0 )"),2.325E10) -> 23250000000 | H23: - | I23: - | J23: - | K23: - | L23: -
B24: Depreciation & Amortization Expense | C24: =Data!B10 -> 3.21B | D24: =Data!C10 -> 3.91B | E24: =Data!D10 -> 3.87B | F24: =Data!E10 -> 4.5B | G24: =Data!F10 -> 5.84B | H24: - | I24: - | J24: - | K24: - | L24: -
B25: Unusual Expense | C25: =Data!B21 -> 3.16B | D25: =Data!C21 -> 2.27B | E25: =Data!D21 -> 1.03B | F25: =Data!E21 -> 1.18B | G25: =Data!F21 -> 1.7B | H25: - | I25: - | J25: - | K25: - | L25: -
B26: Operating Expenses | C26: =C23 -> 19820000000 | D26: =D23 -> 21770000000 | E26: =E23 -> 40910000000 | F26: =F23 -> 26530000000 | G26: =G23 -> 23250000000 | H26: =G26*(1+H27) -> 24196513023 | I26: =H26*(1+I27) -> 25181558816 | J26: =I26*(1+J27) -> 26206706057 | K26: =J26*(1+K27) -> 27273587286 | L26: =K26*(1+L27) -> 28383901503
B27: Operating Expenses Growth | C27: - | D27: =D26/C26-1 -> 0.098385469 | E27: =E26/D26-1 -> 0.87919155 | F27: =F26/E26-1 -> -0.3515033 | G27: =G26/F26-1 -> -0.12363362 | H27: =(G26/C26)^(1/4)-1 -> 0.040710238 | I27: =H27 -> 0.040710238 | J27: =I27 -> 0.040710238 | K27: =J27 -> 0.040710238 | L27: =K27 -> 0.040710238
B28: Operating Income | C28: =IFERROR(__xludf.DUMMYFUNCTION("(REGEXREPLACE(C19,""B"","""")*1000000000)-C26"),1.562E10) -> 15620000000 | D28: =IFERROR(__xludf.DUMMYFUNCTION("(REGEXREPLACE(D19,""B"","""")*1000000000)-D26"),1.95E10) -> 19500000000 | E28: =IFERROR(__xludf.DUMMYFUNCTION("(REGEXREPLACE(E19,""B"","""")*1000000000)-E26"),2.98E9) -> 2980000000 | F28: =IFERROR(__xludf.DUMMYFUNCTION("(REGEXREPLACE(F19,""B"","""")*1000000000)-F26"),2.064E10) -> 20640000000 | G28: =IFERROR(__xludf.DUMMYFUNCTION("(REGEXREPLACE(G19,""B"","""")*1000000000)-G26"),2.348E10) -> 23480000000 | H28: =G28*(1+H29) -> 25998743439 | I28: =H28*(1+I29) -> 29047664625 | J28: =I28*(1+J29) -> 32744615136 | K28: =J28*(1+K29) -> 37239529593 | L28: =K28*(1+L29) -> 42723864646
B29: Operating Income Growth | C29: - | D29: =D28/C28-1 -> 0.24839949 | E29: =E28/D28-1 -> -0.84717949 | F29: =F28/E28-1 -> 5.9261745 | G29: =G28/F28-1 -> 0.1375969 | H29: =(G28/C28)^(1/4)-1 -> 0.10727187 | I29: =H29+1% -> 0.11727187 | J29: =I29+1% -> 0.12727187 | K29: =J29+1% -> 0.13727187 | L29: =K29+1% -> 0.14727187
B32: EBIT | C32: =Data!B22 -> 12.46B | D32: =Data!C22 -> 17.23B | E32: =Data!D22 -> 1.95B | F32: =Data!E22 -> 19.47B | G32: =Data!F22 -> 21.78B | H32: - | I32: - | J32: - | K32: - | L32: -
B33: EBITDA | C33: =IFERROR(__xludf.DUMMYFUNCTION("IFERROR( LET( x, UPPER(SUBSTITUTE(TRIM(Data!B59),CHAR(160),"""")), base, VALUE(SUBSTITUTE(REGEXEXTRACT(x,""[0-9.,]+""),"","","""")), mult, IF(REGEXMATCH(x,""B""),1000000000, IF(REGEXMATCH(x,""M""),1000000, 1)), base * mult ), 0 )"),1.883E10) -> 18830000000 | D33: =IFERROR(__xludf.DUMMYFUNCTION("IFERROR( LET( x, UPPER(SUBSTITUTE(TRIM(Data!C59),CHAR(160),"""")), base, VALUE(SUBSTITUTE(REGEXEXTRACT(x,""[0-9.,]+""),"","","""")), mult, IF(REGEXMATCH(x,""B""),1000000000, IF(REGEXMATCH(x,""M""),1000000, 1)), base * mult ), 0 )"),2.341E10) -> 23410000000 | E33: =IFERROR(__xludf.DUMMYFUNCTION("IFERROR( LET( x, UPPER(SUBSTITUTE(TRIM(Data!D59),CHAR(160),"""")), base, VALUE(SUBSTITUTE(REGEXEXTRACT(x,""[0-9.,]+""),"","","""")), mult, IF(REGEXMATCH(x,""B""),1000000000, IF(REGEXMATCH(x,""M""),1000000, 1)), base * mult ), 0 )"),6.85E9) -> 6850000000 | F33: =IFERROR(__xludf.DUMMYFUNCTION("IFERROR( LET( x, UPPER(SUBSTITUTE(TRIM(Data!E59),CHAR(160),"""")), base, VALUE(SUBSTITUTE(REGEXEXTRACT(x,""[0-9.,]+""),"","","""")), mult, IF(REGEXMATCH(x,""B""),1000000000, IF(REGEXMATCH(x,""M""),1000000, 1)), base * mult ), 0 )"),2.514E10) -> 25140000000 | G33: =IFERROR(__xludf.DUMMYFUNCTION("IFERROR( LET( x, UPPER(SUBSTITUTE(TRIM(Data!F59),CHAR(160),"""")), base, VALUE(SUBSTITUTE(REGEXEXTRACT(x,""[0-9.,]+""),"","","""")), mult, IF(REGEXMATCH(x,""B""),1000000000, IF(REGEXMATCH(x,""M""),1000000, 1)), base * mult ), 0 )"),2.932E10) -> 29320000000 | H33: =G33*(1+H34) -> 32752343298 | I33: =H33*(1+I34) -> 36586493571 | J33: =I33*(1+J34) -> 40869488319 | K33: =J33*(1+K34) -> 45653871482 | L33: =K33*(1+L34) -> 50998338051
B34: EBITDA Growth | C34: =Data!B60 -> - | D34: =Data!C60 -> 0.243 | E34: =Data!D60 -> -0.7072 | F34: =Data!E60 -> 2.6684 | G34: =Data!F60 -> 0.1663 | H34: =(G33/C33)^(1/4)-1 -> 0.11706491 | I34: =H34 -> 0.11706491 | J34: =I34 -> 0.11706491 | K34: =J34 -> 0.11706491 | L34: =K34 -> 0.11706491
B35: EBITDA Margin | C35: =Data!B61 -> - | D35: =Data!C61 -> - | E35: =Data!D61 -> - | F35: =Data!E61 -> - | G35: =Data!F61 -> 0.4517
B38: Pretax Income | C38: =Data!B30 -> 13.88B | D38: =Data!C30 -> 16.44B | E38: =Data!D30 -> 1.89B | F38: =Data!E30 -> 19.94B | G38: =Data!F30 -> 21.07B | H38: - | I38: - | J38: - | K38: - | L38: -
B39: Income Tax | C39: =Data!B33 -> 1.52B | D39: =Data!C33 -> 1.92B | E39: =Data!D33 -> 1.51B | F39: =Data!E33 -> 2.8B | G39: =Data!F33 -> 2.8B | H39: - | I39: - | J39: - | K39: - | L39: -
B40: Net Income | C40: =IFERROR(__xludf.DUMMYFUNCTION("IFERROR( LET( x, UPPER(SUBSTITUTE(TRIM(Data!B43),CHAR(160),"""")), base, VALUE(SUBSTITUTE(REGEXEXTRACT(x,""[0-9.,]+""),"","","""")), mult, IF(REGEXMATCH(x,""B""),1000000000, IF(REGEXMATCH(x,""M""),1000000, 1)), base * mult ), 0 )"),1.235E10) -> 12350000000 | D40: =IFERROR(__xludf.DUMMYFUNCTION("IFERROR( LET( x, UPPER(SUBSTITUTE(TRIM(Data!C43),CHAR(160),"""")), base, VALUE(SUBSTITUTE(REGEXEXTRACT(x,""[0-9.,]+""),"","","""")), mult, IF(REGEXMATCH(x,""B""),1000000000, IF(REGEXMATCH(x,""M""),1000000, 1)), base * mult ), 0 )"),1.452E10) -> 14520000000 | E40: =IFERROR(__xludf.DUMMYFUNCTION("IFERROR( LET( x, UPPER(SUBSTITUTE(TRIM(Data!D43),CHAR(160),"""")), base, VALUE(SUBSTITUTE(REGEXEXTRACT(x,""[0-9.,]+""),"","","""")), mult, IF(REGEXMATCH(x,""B""),1000000000, IF(REGEXMATCH(x,""M""),1000000, 1)), base * mult ), 0 )"),3.65E8) -> 365000000 | F40: =IFERROR(__xludf.DUMMYFUNCTION("IFERROR( LET( x, UPPER(SUBSTITUTE(TRIM(Data!E43),CHAR(160),"""")), base, VALUE(SUBSTITUTE(REGEXEXTRACT(x,""[0-9.,]+""),"","","""")), mult, IF(REGEXMATCH(x,""B""),1000000000, IF(REGEXMATCH(x,""M""),1000000, 1)), base * mult ), 0 )"),1.7120000000000002E10) -> 17120000000 | G40: =IFERROR(__xludf.DUMMYFUNCTION("IFERROR( LET( x, UPPER(SUBSTITUTE(TRIM(Data!F43),CHAR(160),"""")), base, VALUE(SUBSTITUTE(REGEXEXTRACT(x,""[0-9.,]+""),"","","""")), mult, IF(REGEXMATCH(x,""B""),1000000000, IF(REGEXMATCH(x,""M""),1000000, 1)), base * mult ), 0 )"),1.825E10) -> 18250000000 | H40: =G40*(1+H42) -> 13794566667 | I40: =H40*(1+I42) -> 8494540880 | J40: =I40*(1+J42) -> 6903387528 | K40: =J40*(1+K42) -> 5610280772 | L40: =K40*(1+L42) -> 4203539231
B41: Net Income to Common | C41: =Data!B52 -> 13.05B | D41: =Data!C52 -> 14.52B | E41: =Data!D52 -> 365M | F41: =Data!E52 -> 17.12B | G41: =Data!F52 -> 18.25B | H41: - | I41: - | J41: - | K41: - | L41: -
B42: Net Income Growth | C42: =Data!B44 -> - | D42: =Data!C44 -> 0.1761 | E42: =Data!D44 -> -0.9749 | F42: =Data!E44 -> 45.8959 | G42: =Data!F44 -> 0.0664 | H42: =AVERAGEIF(D42:G42,"<0.70") -> -0.24413333 | I42: =AVERAGEIF(E42:H42,"<0.80") -> -0.38421111 | J42: =AVERAGEIF(F42:I42,"<0.80") -> -0.18731481 | K42: =AVERAGEIF(G42:J42,"<0.80") -> -0.18731481 | L42: =AVERAGEIF(H42:K42,"<0.80") -> -0.25074352
B45: EPS (Diluted) | C45: =Data!B56 -> 5.14 | D45: =Data!C56 -> 5.71 | E45: =Data!D56 -> 0.14 | F45: =Data!E56 -> 6.74 | G45: =Data!F56 -> 7.28 | H45: =Forecast(H12,$C$45:G45,$C$12:G12) -> 6.595 | I45: =FORECAST(I12,$C$45:H45,$C$12:H12) -> 7.126 | J45: =FORECAST(J12,$C$45:I45,$C$12:I12) -> 7.657 | K45: =FORECAST(K12,$C$45:J45,$C$12:J12) -> 8.188 | L45: =FORECAST(L12,$C$45:K45,$C$12:K12) -> 8.719
B46: EPS (Diluted) Growth | C46: =Data!B57 -> - | D46: =Data!C57 -> 0.1109 | E46: =Data!D57 -> -0.9749 | F46: =Data!E57 -> 46.0084 | G46: =Data!F57 -> 0.0809 | H46: =H45/G45-1 -> -0.094093407 | I46: =I45/H45-1 -> 0.080515542 | J46: =J45/I45-1 -> 0.074515857 | K46: =K45/J45-1 -> 0.069348309 | L46: =L45/K45-1 -> 0.064851001
D1006: =1.56*L33 -> 79557407359

Sheet Balance Sheet
B2: Balance Sheet | C2: FY | H2: Future FY
C3: 2020 | D3: 2021 | E3: 2022 | F3: 2023 | G3: 2024 | H3: 2025 | I3: 2026 | J3: 2027 | K3: 2028 | L3: 2029
B6: Cash Only | C6: =IFERROR(__xludf.DUMMYFUNCTION("IFERROR( LET( x, UPPER(SUBSTITUTE(TRIM(Data!B71),CHAR(160),"""")), base, VALUE(SUBSTITUTE(REGEXEXTRACT(x,""[0-9.,]+""),"","","""")), mult, IF(REGEXMATCH(x,""B""),1000000000, IF(REGEXMATCH(x,""M""),1000000, 1)), base * mult ), 0 )"),8.1E9) -> 8100000000 | D6: =IFERROR(__xludf.DUMMYFUNCTION("IFERROR( LET( x, UPPER(SUBSTITUTE(TRIM(Data!C71),CHAR(160),"""")), base, VALUE(SUBSTITUTE(REGEXEXTRACT(x,""[0-9.,]+""),"","","""")), mult, IF(REGEXMATCH(x,""B""),1000000000, IF(REGEXMATCH(x,""M""),1000000, 1)), base * mult ), 0 )"),1.277E10) -> 12770000000 | E6: =IFERROR(__xludf.DUMMYFUNCTION("IFERROR( LET( x, UPPER(SUBSTITUTE(TRIM(Data!D71),CHAR(160),"""")), base, VALUE(SUBSTITUTE(REGEXEXTRACT(x,""[0-9.,]+""),"","","""")), mult, IF(REGEXMATCH(x,""B""),1000000000, IF(REGEXMATCH(x,""M""),1000000, 1)), base * mult ), 0 )"),6.91E9) -> 6910000000 | F6: =IFERROR(__xludf.DUMMYFUNCTION("IFERROR( LET( x, UPPER(SUBSTITUTE(TRIM(Data!E71),CHAR(160),"""")), base, VALUE(SUBSTITUTE(REGEXEXTRACT(x,""[0-9.,]+""),"","","""")), mult, IF(REGEXMATCH(x,""B""),1000000000, IF(REGEXMATCH(x,""M""),1000000, 1)), base * mult ), 0 )"),1.332E10) -> 13320000000 | G6: =IFERROR(__xludf.DUMMYFUNCTION("IFERROR( LET( x, UPPER(SUBSTITUTE(TRIM(Data!F71),CHAR(160),"""")), base, VALUE(SUBSTITUTE(REGEXEXTRACT(x,""[0-9.,]+""),"","","""")), mult, IF(REGEXMATCH(x,""B""),1000000000, IF(REGEXMATCH(x,""M""),1000000, 1)), base * mult ), 0 )"),1.469E10) -> 14690000000 | H6: =FORECAST(H3,$C$6:G6,$C$3:G3) -> 15277000000 | I6: =FORECAST(I3,$C$6:H6,$C$3:H3) -> 16650000000 | J6: =FORECAST(J3,$C$6:I6,$C$3:I3) -> 18023000000 | K6: =FORECAST(K3,$C$6:J6,$C$3:J3) -> 19396000000 | L6: =FORECAST(L3,$C$6:K6,$C$3:K3) -> 20769000000
B7: Short-Term Investments | C7: =Data!B72:F72 -> - | D7: =Data!C72 -> - | E7: =Data!D72 -> - | F7: =Data!E72 -> - | G7: =Data!F72 -> - | H7: - | I7: - | J7: - | K7: - | L7: -
B8: Cash & Short Term Invesments | C8: =IFERROR(__xludf.DUMMYFUNCTION("IFERROR( LET( x, UPPER(SUBSTITUTE(TRIM(Data!B69),CHAR(160),"""")), base, VALUE(SUBSTITUTE(REGEXEXTRACT(x,""[0-9.,]+""),"","","""")), mult, IF(REGEXMATCH(x,""B""),1000000000, IF(REGEXMATCH(x,""M""),1000000, 1)), base * mult ), 0 )"),8.1E9) -> 8100000000 | D8: =IFERROR(__xludf.DUMMYFUNCTION("IFERROR( LET( x, UPPER(SUBSTITUTE(TRIM(Data!C69),CHAR(160),"""")), base, VALUE(SUBSTITUTE(REGEXEXTRACT(x,""[0-9.,]+""),"","","""")), mult, IF(REGEXMATCH(x,""B""),1000000000, IF(REGEXMATCH(x,""M""),1000000, 1)), base * mult ), 0 )"),1.327E10) -> 13270000000 | E8: =IFERROR(__xludf.DUMMYFUNCTION("IFERROR( LET( x, UPPER(SUBSTITUTE(TRIM(Data!D69),CHAR(160),"""")), base, VALUE(SUBSTITUTE(REGEXEXTRACT(x,""[0-9.,]+""),"","","""")), mult, IF(REGEXMATCH(x,""B""),1000000000, IF(REGEXMATCH(x,""M""),1000000, 1)), base * mult ), 0 )"),7.16E9) -> 7160000000 | F8: =IFERROR(__xludf.DUMMYFUNCTION("IFERROR( LET( x, UPPER(SUBSTITUTE(TRIM(Data!E69),CHAR(160),"""")), base, VALUE(SUBSTITUTE(REGEXEXTRACT(x,""[0-9.,]+""),"","","""")), mult, IF(REGEXMATCH(x,""B""),1000000000, IF(REGEXMATCH(x,""M""),1000000, 1)), base * mult ), 0 )"),1.377E10) -> 13770000000 | G8: =IFERROR(__xludf.DUMMYFUNCTION("IFERROR( LET( x, UPPER(SUBSTITUTE(TRIM(Data!F69),CHAR(160),"""")), base, VALUE(SUBSTITUTE(REGEXEXTRACT(x,""[0-9.,]+""),"","","""")), mult, IF(REGEXMATCH(x,""B""),1000000000, IF(REGEXMATCH(x,""M""),1000000, 1)), base * mult ), 0 )"),1.469E10) -> 14690000000 | H8: =H6 -> 15277000000 | I8: =I6 -> 16650000000 | J8: =J6 -> 18023000000 | K8: =K6 -> 19396000000 | L8: =L6 -> 20769000000
B9: Cash & Short Term Invesments Growth | C9: =Data!B70 -> - | D9: =Data!C70 -> 0.6392 | E9: =Data!D70 -> -0.4604 | F9: =Data!E70 -> 0.9222 | G9: =Data!F70 -> 0.0672 | H9: =H8/G8-1 -> 0.039959156 | I9: =I8/H8-1 -> 0.089873666 | J9: =J8/I8-1 -> 0.082462462 | K9: =K8/J8-1 -> 0.076180436 | L9: =L8/K8-1 -> 0.070787791
B12: Finished Goods | C12: =IFERROR(__xludf.DUMMYFUNCTION("IFERROR( LET( x, UPPER(SUBSTITUTE(TRIM(Data!B82),CHAR(160),"""")), base, VALUE(SUBSTITUTE(REGEXEXTRACT(x,""[0-9.,]+""),"","","""")), mult, IF(REGEXMATCH(x,""B""),1000000000, IF(REGEXMATCH(x,""M""),1000000, 1)), base * mult ), 0 )"),1.75E9) -> 1750000000 | D12: =IFERROR(__xludf.DUMMYFUNCTION("IFERROR( LET( x, UPPER(SUBSTITUTE(TRIM(Data!C82),CHAR(160),"""")), base, VALUE(SUBSTITUTE(REGEXEXTRACT(x,""[0-9.,]+""),"","","""")), mult, IF(REGEXMATCH(x,""B""),1000000000, IF(REGEXMATCH(x,""M""),1000000, 1)), base * mult ), 0 )"),1.84E9) -> 1840000000 | E12: =IFERROR(__xludf.DUMMYFUNCTION("IFERROR( LET( x, UPPER(SUBSTITUTE(TRIM(Data!D82),CHAR(160),"""")), base, VALUE(SUBSTITUTE(REGEXEXTRACT(x,""[0-9.,]+""),"","","""")), mult, IF(REGEXMATCH(x,""B""),1000000000, IF(REGEXMATCH(x,""M""),1000000, 1)), base * mult ), 0 )"),1.95E9) -> 1950000000 | F12: =IFERROR(__xludf.DUMMYFUNCTION("IFERROR( LET( x, UPPER(SUBSTITUTE(TRIM(Data!E82),CHAR(160),"""")), base, VALUE(SUBSTITUTE(REGEXEXTRACT(x,""[0-9.,]+""),"","","""")), mult, IF(REGEXMATCH(x,""B""),1000000000, IF(REGEXMATCH(x,""M""),1000000, 1)), base * mult ), 0 )"),2.02E9) -> 2020000000 | G12: =IFERROR(__xludf.DUMMYFUNCTION("IFERROR( LET( x, UPPER(SUBSTITUTE(TRIM(Data!F82),CHAR(160),"""")), base, VALUE(SUBSTITUTE(REGEXEXTRACT(x,""[0-9.,]+""),"","","""")), mult, IF(REGEXMATCH(x,""B""),1000000000, IF(REGEXMATCH(x,""M""),1000000, 1)), base * mult ), 0 )"),2.28E9) -> 2280000000 | H12: =AVERAGE(C12:G12) -> 1968000000 | I12: =AVERAGE(D12:H12) -> 2011600000 | J12: =AVERAGE(E12:I12) -> 2045920000 | K12: =AVERAGE(F12:J12) -> 2065104000 | L12: =AVERAGE(G12:K12) -> 2074124800
B13: Work in Progress | C13: =IFERROR(__xludf.DUMMYFUNCTION("regexreplace(Data!B83,""M"","""")*1000000"),"#VALUE!") -> #VALUE! | D13: =IFERROR(__xludf.DUMMYFUNCTION("IFERROR( LET( x, UPPER(SUBSTITUTE(TRIM(Data!C83),CHAR(160),"""")), base, VALUE(SUBSTITUTE(REGEXEXTRACT(x,""[0-9.,]+""),"","","""")), mult, IF(REGEXMATCH(x,""B""),1000000000, IF(REGEXMATCH(x,""M""),1000000, 1)), base * mult ), 0 )"),0.0) -> 0 | E13: =IFERROR(__xludf.DUMMYFUNCTION("IFERROR( LET( x, UPPER(SUBSTITUTE(TRIM(Data!D83),CHAR(160),"""")), base, VALUE(SUBSTITUTE(REGEXEXTRACT(x,""[0-9.,]+""),"","","""")), mult, IF(REGEXMATCH(x,""B""),1000000000, IF(REGEXMATCH(x,""M""),1000000, 1)), base * mult ), 0 )"),0.0) -> 0 | F13: =IFERROR(__xludf.DUMMYFUNCTION("IFERROR( LET( x, UPPER(SUBSTITUTE(TRIM(Data!E83),CHAR(160),"""")), base, VALUE(SUBSTITUTE(REGEXEXTRACT(x,""[0-9.,]+""),"","","""")), mult, IF(REGEXMATCH(x,""B""),1000000000, IF(REGEXMATCH(x,""M""),1000000, 1)), base * mult ), 0 )"),0.0) -> 0 | G13: =IFERROR(__xludf.DUMMYFUNCTION("IFERROR( LET( x, UPPER(SUBSTITUTE(TRIM(Data!F83),CHAR(160),"""")), base, VALUE(SUBSTITUTE(REGEXEXTRACT(x,""[0-9.,]+""),"","","""")), mult, IF(REGEXMATCH(x,""B""),1000000000, IF(REGEXMATCH(x,""M""),1000000, 1)), base * mult ), 0 )"),0.0) -> 0 | H13: =AVERAGE(C13:G13) -> #VALUE! | I13: =AVERAGE(D13:H13) -> #VALUE! | J13: =AVERAGE(E13:I13) -> #VALUE! | K13: =AVERAGE(F13:J13) -> #VALUE! | L13: =AVERAGE(G13:K13) -> #VALUE!
B14: Raw Materials | C14: =IFERROR(__xludf.DUMMYFUNCTION("IFERROR( LET( x, UPPER(SUBSTITUTE(TRIM(Data!B84),CHAR(160),"""")), base, VALUE(SUBSTITUTE(REGEXEXTRACT(x,""[0-9.,]+""),"","","""")), mult, IF(REGEXMATCH(x,""B""),1000000000, IF(REGEXMATCH(x,""M""),1000000, 1)), base * mult ), 0 )"),4.2199999999999995E9) -> 4220000000 | D14: =IFERROR(__xludf.DUMMYFUNCTION("IFERROR( LET( x, UPPER(SUBSTITUTE(TRIM(Data!C84),CHAR(160),"""")), base, VALUE(SUBSTITUTE(REGEXEXTRACT(x,""[0-9.,]+""),"","","""")), mult, IF(REGEXMATCH(x,""B""),1000000000, IF(REGEXMATCH(x,""M""),1000000, 1)), base * mult ), 0 )"),4.36E9) -> 4360000000 | E14: =IFERROR(__xludf.DUMMYFUNCTION("IFERROR( LET( x, UPPER(SUBSTITUTE(TRIM(Data!D84),CHAR(160),"""")), base, VALUE(SUBSTITUTE(REGEXEXTRACT(x,""[0-9.,]+""),"","","""")), mult, IF(REGEXMATCH(x,""B""),1000000000, IF(REGEXMATCH(x,""M""),1000000, 1)), base * mult ), 0 )"),4.97E9) -> 4970000000 | F14: =IFERROR(__xludf.DUMMYFUNCTION("IFERROR( LET( x, UPPER(SUBSTITUTE(TRIM(Data!E84),CHAR(160),"""")), base, VALUE(SUBSTITUTE(REGEXEXTRACT(x,""[0-9.,]+""),"","","""")), mult, IF(REGEXMATCH(x,""B""),1000000000, IF(REGEXMATCH(x,""M""),1000000, 1)), base * mult ), 0 )"),4.93E9) -> 4930000000 | G14: =IFERROR(__xludf.DUMMYFUNCTION("IFERROR( LET( x, UPPER(SUBSTITUTE(TRIM(Data!F84),CHAR(160),"""")), base, VALUE(SUBSTITUTE(REGEXEXTRACT(x,""[0-9.,]+""),"","","""")), mult, IF(REGEXMATCH(x,""B""),1000000000, IF(REGEXMATCH(x,""M""),1000000, 1)), base * mult ), 0 )"),5.3E9) -> 5300000000 | H14: =AVERAGE(C14:G14) -> 4756000000 | I14: =AVERAGE(D14:H14) -> 4863200000 | J14: =AVERAGE(E14:I14) -> 4963840000 | K14: =AVERAGE(F14:J14) -> 4962608000 | L14: =AVERAGE(G14:K14) -> 4969129600
B15: Inventories | C15: =IFERROR(__xludf.DUMMYFUNCTION("IFERROR( LET( x, UPPER(SUBSTITUTE(TRIM(Data!B81),CHAR(160),"""")), base, VALUE(SUBSTITUTE(REGEXEXTRACT(x,""[0-9.,]+""),"","","""")), mult, IF(REGEXMATCH(x,""B""),1000000000, IF(REGEXMATCH(x,""M""),1000000, 1)), base * mult ), 0 )"),5.95E9) -> 5950000000 | D15: =IFERROR(__xludf.DUMMYFUNCTION("IFERROR( LET( x, UPPER(SUBSTITUTE(TRIM(Data!C81),CHAR(160),"""")), base, VALUE(SUBSTITUTE(REGEXEXTRACT(x,""[0-9.,]+""),"","","""")), mult, IF(REGEXMATCH(x,""B""),1000000000, IF(REGEXMATCH(x,""M""),1000000, 1)), base * mult ), 0 )"),5.91E9) -> 5910000000 | E15: =IFERROR(__xludf.DUMMYFUNCTION("IFERROR( LET( x, UPPER(SUBSTITUTE(TRIM(Data!D81),CHAR(160),"""")), base, VALUE(SUBSTITUTE(REGEXEXTRACT(x,""[0-9.,]+""),"","","""")), mult, IF(REGEXMATCH(x,""B""),1000000000, IF(REGEXMATCH(x,""M""),1000000, 1)), base * mult ), 0 )"),6.36E9) -> 6360000000 | F15: =IFERROR(__xludf.DUMMYFUNCTION("IFERROR( LET( x, UPPER(SUBSTITUTE(TRIM(Data!E81),CHAR(160),"""")), base, VALUE(SUBSTITUTE(REGEXEXTRACT(x,""[0-9.,]+""),"","","""")), mult, IF(REGEXMATCH(x,""B""),1000000000, IF(REGEXMATCH(x,""M""),1000000, 1)), base * mult ), 0 )"),6.11E9) -> 6110000000 | G15: =IFERROR(__xludf.DUMMYFUNCTION("IFERROR( LET( x, UPPER(SUBSTITUTE(TRIM(Data!F81),CHAR(160),"""")), base, VALUE(SUBSTITUTE(REGEXEXTRACT(x,""[0-9.,]+""),"","","""")), mult, IF(REGEXMATCH(x,""B""),1000000000, IF(REGEXMATCH(x,""M""),1000000, 1)), base * mult ), 0 )"),6.66E9) -> 6660000000 | H15: =AVERAGE(C15:G15) -> 6198000000 | I15: =AVERAGE(D15:H15) -> 6247600000 | J15: =AVERAGE(E15:I15) -> 6315120000 | K15: =AVERAGE(F15:J15) -> 6306144000 | L15: =AVERAGE(G15:K15) -> 6345372800
B18: Accounts Receivables, Net | C18: =IFERROR(__xludf.DUMMYFUNCTION("IFERROR( LET( x, UPPER(SUBSTITUTE(TRIM(Data!B76),CHAR(160),"""")), base, VALUE(SUBSTITUTE(REGEXEXTRACT(x,""[0-9.,]+""),"","","""")), mult, IF(REGEXMATCH(x,""B""),1000000000, IF(REGEXMATCH(x,""M""),1000000, 1)), base * mult ), 0 )"),9.23E9) -> 9230000000 | D18: =IFERROR(__xludf.DUMMYFUNCTION("IFERROR( LET( x, UPPER(SUBSTITUTE(TRIM(Data!C76),CHAR(160),"""")), base, VALUE(SUBSTITUTE(REGEXEXTRACT(x,""[0-9.,]+""),"","","""")), mult, IF(REGEXMATCH(x,""B""),1000000000, IF(REGEXMATCH(x,""M""),1000000, 1)), base * mult ), 0 )"),9.45E9) -> 9450000000 | E18: =IFERROR(__xludf.DUMMYFUNCTION("IFERROR( LET( x, UPPER(SUBSTITUTE(TRIM(Data!D76),CHAR(160),"""")), base, VALUE(SUBSTITUTE(REGEXEXTRACT(x,""[0-9.,]+""),"","","""")), mult, IF(REGEXMATCH(x,""B""),1000000000, IF(REGEXMATCH(x,""M""),1000000, 1)), base * mult ), 0 )"),1.035E10) -> 10350000000 | F18: =IFERROR(__xludf.DUMMYFUNCTION("IFERROR( LET( x, UPPER(SUBSTITUTE(TRIM(Data!E76),CHAR(160),"""")), base, VALUE(SUBSTITUTE(REGEXEXTRACT(x,""[0-9.,]+""),"","","""")), mult, IF(REGEXMATCH(x,""B""),1000000000, IF(REGEXMATCH(x,""M""),1000000, 1)), base * mult ), 0 )"),1.028E10) -> 10280000000 | G18: =IFERROR(__xludf.DUMMYFUNCTION("IFERROR( LET( x, UPPER(SUBSTITUTE(TRIM(Data!F76),CHAR(160),"""")), base, VALUE(SUBSTITUTE(REGEXEXTRACT(x,""[0-9.,]+""),"","","""")), mult, IF(REGEXMATCH(x,""B""),1000000000, IF(REGEXMATCH(x,""M""),1000000, 1)), base * mult ), 0 )"),1.178E10) -> 11780000000 | H18: =FORECAST(H3,$C$18:G18,$C$3:G3) -> 11997000000 | I18: =FORECAST(I3,$C$18:H18,$C$3:H3) -> 12590000000 | J18: =FORECAST(J3,$C$18:I18,$C$3:I3) -> 13183000000 | K18: =FORECAST(K3,$C$18:J18,$C$3:J3) -> 13776000000 | L18: =FORECAST(L3,$C$18:K18,$C$3:K3) -> 14369000000
B19: Other Receivable | C19: =Data!B79 -> 585M | D19: =Data!C79 -> 660M | E19: =Data!D79 -> 723M | F19: =Data!E79 -> 849M | G19: =Data!F79 -> 904M | H19: - | I19: - | J19: - | K19: - | L19: -
B20: Total Accounts Receivable | C20: =IFERROR(__xludf.DUMMYFUNCTION("IFERROR( LET( x, UPPER(SUBSTITUTE(TRIM(Data!B74),CHAR(160),"""")), base, VALUE(SUBSTITUTE(REGEXEXTRACT(x,""[0-9.,]+""),"","","""")), mult, IF(REGEXMATCH(x,""B""),1000000000, IF(REGEXMATCH(x,""M""),1000000, 1)), base * mult ), 0 )"),9.82E9) -> 9820000000 | D20: =IFERROR(__xludf.DUMMYFUNCTION("IFERROR( LET( x, UPPER(SUBSTITUTE(TRIM(Data!C74),CHAR(160),"""")), base, VALUE(SUBSTITUTE(REGEXEXTRACT(x,""[0-9.,]+""),"","","""")), mult, IF(REGEXMATCH(x,""B""),1000000000, IF(REGEXMATCH(x,""M""),1000000, 1)), base * mult ), 0 )"),1.011E10) -> 10110000000 | E20: =IFERROR(__xludf.DUMMYFUNCTION("IFERROR( LET( x, UPPER(SUBSTITUTE(TRIM(Data!D74),CHAR(160),"""")), base, VALUE(SUBSTITUTE(REGEXEXTRACT(x,""[0-9.,]+""),"","","""")), mult, IF(REGEXMATCH(x,""B""),1000000000, IF(REGEXMATCH(x,""M""),1000000, 1)), base * mult ), 0 )"),1.107E10) -> 11070000000 | F20: =IFERROR(__xludf.DUMMYFUNCTION("IFERROR( LET( x, UPPER(SUBSTITUTE(TRIM(Data!E74),CHAR(160),"""")), base, VALUE(SUBSTITUTE(REGEXEXTRACT(x,""[0-9.,]+""),"","","""")), mult, IF(REGEXMATCH(x,""B""),1000000000, IF(REGEXMATCH(x,""M""),1000000, 1)), base * mult ), 0 )"),1.113E10) -> 11130000000 | G20: =IFERROR(__xludf.DUMMYFUNCTION("IFERROR( LET( x, UPPER(SUBSTITUTE(TRIM(Data!F74),CHAR(160),"""")), base, VALUE(SUBSTITUTE(REGEXEXTRACT(x,""[0-9.,]+""),"","","""")), mult, IF(REGEXMATCH(x,""B""),1000000000, IF(REGEXMATCH(x,""M""),1000000, 1)), base * mult ), 0 )"),1.268E10) -> 12680000000 | H20: =FORECAST(H3,$C$20:G20,$C$3:G3) -> 12984000000 | I20: =FORECAST(I3,$C$20:H20,$C$3:H3) -> 13658000000 | J20: =FORECAST(J3,$C$20:I20,$C$3:I3) -> 14332000000 | K20: =FORECAST(K3,$C$20:J20,$C$3:J3) -> 15006000000 | L20: =FORECAST(L3,$C$20:K20,$C$3:K3) -> 15680000000
B21: Total Accounts Receivable Growth | C21: =Data!B75 -> - | D21: =Data!C75 -> 0.0301 | E21: =Data!D75 -> 0.0952 | F21: =Data!E75 -> 0.005 | G21: =Data!F75 -> 0.1395 | H21: =H20/G20-1 -> 0.023974763 | I21: =I20/H20-1 -> 0.051910043 | J21: =J20/I20-1 -> 0.049348367 | K21: =K20/J20-1 -> 0.04702763 | L21: =L20/K20-1 -> 0.044915367
B24: Other Current Assets | C24: =IFERROR(__xludf.DUMMYFUNCTION("IFERROR( LET( x, UPPER(SUBSTITUTE(TRIM(Data!B86),CHAR(160),"""")), base, VALUE(SUBSTITUTE(REGEXEXTRACT(x,""[0-9.,]+""),"","","""")), mult, IF(REGEXMATCH(x,""B""),1000000000, IF(REGEXMATCH(x,""M""),1000000, 1)), base * mult ), 0 )"),6.4E9) -> 6400000000 | D24: =IFERROR(__xludf.DUMMYFUNCTION("IFERROR( LET( x, UPPER(SUBSTITUTE(TRIM(Data!C86),CHAR(160),"""")), base, VALUE(SUBSTITUTE(REGEXEXTRACT(x,""[0-9.,]+""),"","","""")), mult, IF(REGEXMATCH(x,""B""),1000000000, IF(REGEXMATCH(x,""M""),1000000, 1)), base * mult ), 0 )"),6.43E9) -> 6430000000 | E24: =IFERROR(__xludf.DUMMYFUNCTION("IFERROR( LET( x, UPPER(SUBSTITUTE(TRIM(Data!D86),CHAR(160),"""")), base, VALUE(SUBSTITUTE(REGEXEXTRACT(x,""[0-9.,]+""),"","","""")), mult, IF(REGEXMATCH(x,""B""),1000000000, IF(REGEXMATCH(x,""M""),1000000, 1)), base * mult ), 0 )"),7.58E9) -> 7580000000 | F24: =IFERROR(__xludf.DUMMYFUNCTION("IFERROR( LET( x, UPPER(SUBSTITUTE(TRIM(Data!E86),CHAR(160),"""")), base, VALUE(SUBSTITUTE(REGEXEXTRACT(x,""[0-9.,]+""),"","","""")), mult, IF(REGEXMATCH(x,""B""),1000000000, IF(REGEXMATCH(x,""M""),1000000, 1)), base * mult ), 0 )"),7.78E9) -> 7780000000 | G24: =IFERROR(__xludf.DUMMYFUNCTION("IFERROR( LET( x, UPPER(SUBSTITUTE(TRIM(Data!F86),CHAR(160),"""")), base, VALUE(SUBSTITUTE(REGEXEXTRACT(x,""[0-9.,]+""),"","","""")), mult, IF(REGEXMATCH(x,""B""),1000000000, IF(REGEXMATCH(x,""M""),1000000, 1)), base * mult ), 0 )"),9.49E9) -> 9490000000 | H24: =AVERAGE(C24:G24) -> 7536000000 | I24: =AVERAGE(D24:H24) -> 7763200000 | J24: =AVERAGE(E24:I24) -> 8029840000 | K24: =AVERAGE(F24:J24) -> 8119808000 | L24: =AVERAGE(G24:K24) -> 8187769600
B25: Total Current Assets | C25: =IFERROR(__xludf.DUMMYFUNCTION("IFERROR( LET( x, UPPER(SUBSTITUTE(TRIM(Data!B88),CHAR(160),"""")), base, VALUE(SUBSTITUTE(REGEXEXTRACT(x,""[0-9.,]+""),"","","""")), mult, IF(REGEXMATCH(x,""B""),1000000000, IF(REGEXMATCH(x,""M""),1000000, 1)), base * mult ), 0 )"),3.027E10) -> 30270000000 | D25: =IFERROR(__xludf.DUMMYFUNCTION("IFERROR( LET( x, UPPER(SUBSTITUTE(TRIM(Data!C88),CHAR(160),"""")), base, VALUE(SUBSTITUTE(REGEXEXTRACT(x,""[0-9.,]+""),"","","""")), mult, IF(REGEXMATCH(x,""B""),1000000000, IF(REGEXMATCH(x,""M""),1000000, 1)), base * mult ), 0 )"),3.572E10) -> 35720000000 | E25: =IFERROR(__xludf.DUMMYFUNCTION("IFERROR( LET( x, UPPER(SUBSTITUTE(TRIM(Data!D88),CHAR(160),"""")), base, VALUE(SUBSTITUTE(REGEXEXTRACT(x,""[0-9.,]+""),"","","""")), mult, IF(REGEXMATCH(x,""B""),1000000000, IF(REGEXMATCH(x,""M""),1000000, 1)), base * mult ), 0 )"),3.217E10) -> 32170000000 | F25: =IFERROR(__xludf.DUMMYFUNCTION("IFERROR( LET( x, UPPER(SUBSTITUTE(TRIM(Data!E88),CHAR(160),"""")), base, VALUE(SUBSTITUTE(REGEXEXTRACT(x,""[0-9.,]+""),"","","""")), mult, IF(REGEXMATCH(x,""B""),1000000000, IF(REGEXMATCH(x,""M""),1000000, 1)), base * mult ), 0 )"),3.878E10) -> 38780000000 | G25: =IFERROR(__xludf.DUMMYFUNCTION("IFERROR( LET( x, UPPER(SUBSTITUTE(TRIM(Data!F88),CHAR(160),"""")), base, VALUE(SUBSTITUTE(REGEXEXTRACT(x,""[0-9.,]+""),"","","""")), mult, IF(REGEXMATCH(x,""B""),1000000000, IF(REGEXMATCH(x,""M""),1000000, 1)), base * mult ), 0 )"),4.352E10) -> 43520000000 | H25: =FORECAST(H3,$C$25:G25,$C$3:G3) -> 44960000000 | I25: =FORECAST(I3,$C$25:H25,$C$3:H3) -> 47916000000 | J25: =FORECAST(J3,$C$25:I25,$C$3:I3) -> 50872000000 | K25: =FORECAST(K3,$C$25:J25,$C$3:J3) -> 53828000000 | L25: =FORECAST(L3,$C$25:K25,$C$3:K3) -> 56784000000
B26: Total Current Assets Growth | C26: - | D26: =D25/C25-1 -> 0.18004625 | E26: =E25/D25-1 -> -0.099384099 | F26: =F25/E25-1 -> 0.20547094 | G26: =G25/F25-1 -> 0.12222795 | H26: =H25/G25-1 -> 0.033088235 | I26: =I25/H25-1 -> 0.065747331 | J26: =J25/I25-1 -> 0.061691293 | K26: =K25/J25-1 -> 0.058106621 | L26: =L25/K25-1 -> 0.054915657
B29: Property, Plant & Equipment | C29: =IFERROR(__xludf.DUMMYFUNCTION("IFERROR( LET( x, UPPER(SUBSTITUTE(TRIM(Data!B90),CHAR(160),"""")), base, VALUE(SUBSTITUTE(REGEXEXTRACT(x,""[0-9.,]+""),"","","""")), mult, IF(REGEXMATCH(x,""B""),1000000000, IF(REGEXMATCH(x,""M""),1000000, 1)), base * mult ), 0 )"),3.906E10) -> 39060000000 | D29: =IFERROR(__xludf.DUMMYFUNCTION("IFERROR( LET( x, UPPER(SUBSTITUTE(TRIM(Data!C90),CHAR(160),"""")), base, VALUE(SUBSTITUTE(REGEXEXTRACT(x,""[0-9.,]+""),"","","""")), mult, IF(REGEXMATCH(x,""B""),1000000000, IF(REGEXMATCH(x,""M""),1000000, 1)), base * mult ), 0 )"),4.075E10) -> 40750000000 | E29: =IFERROR(__xludf.DUMMYFUNCTION("IFERROR( LET( x, UPPER(SUBSTITUTE(TRIM(Data!D90),CHAR(160),"""")), base, VALUE(SUBSTITUTE(REGEXEXTRACT(x,""[0-9.,]+""),"","","""")), mult, IF(REGEXMATCH(x,""B""),1000000000, IF(REGEXMATCH(x,""M""),1000000, 1)), base * mult ), 0 )"),4.275E10) -> 42750000000 | F29: =IFERROR(__xludf.DUMMYFUNCTION("IFERROR( LET( x, UPPER(SUBSTITUTE(TRIM(Data!E90),CHAR(160),"""")), base, VALUE(SUBSTITUTE(REGEXEXTRACT(x,""[0-9.,]+""),"","","""")), mult, IF(REGEXMATCH(x,""B""),1000000000, IF(REGEXMATCH(x,""M""),1000000, 1)), base * mult ), 0 )"),4.43E10) -> 44300000000 | G29: =IFERROR(__xludf.DUMMYFUNCTION("IFERROR( LET( x, UPPER(SUBSTITUTE(TRIM(Data!F90),CHAR(160),"""")), base, VALUE(SUBSTITUTE(REGEXEXTRACT(x,""[0-9.,]+""),"","","""")), mult, IF(REGEXMATCH(x,""B""),1000000000, IF(REGEXMATCH(x,""M""),1000000, 1)), base * mult ), 0 )"),4.874E10) -> 48740000000 | H29: =AVERAGE(C29:G29) -> 43120000000 | I29: =AVERAGE(D29:H29) -> 43932000000 | J29: =AVERAGE(E29:I29) -> 44568400000 | K29: =AVERAGE(F29:J29) -> 44932080000 | L29: =AVERAGE(G29:K29) -> 45058496000
B30: Accumulated Depreciation | C30: =IFERROR(__xludf.DUMMYFUNCTION("IFERROR( LET( x, UPPER(SUBSTITUTE(TRIM(Data!B95),CHAR(160),"""")), base, VALUE(SUBSTITUTE(REGEXEXTRACT(x,""[0-9.,]+""),"","","""")), mult, IF(REGEXMATCH(x,""B""),1000000000, IF(REGEXMATCH(x,""M""),1000000, 1)), base * mult ), 0 )"),1.819E10) -> 18190000000 | D30: =IFERROR(__xludf.DUMMYFUNCTION("IFERROR( LET( x, UPPER(SUBSTITUTE(TRIM(Data!C95),CHAR(160),"""")), base, VALUE(SUBSTITUTE(REGEXEXTRACT(x,""[0-9.,]+""),"","","""")), mult, IF(REGEXMATCH(x,""B""),1000000000, IF(REGEXMATCH(x,""M""),1000000, 1)), base * mult ), 0 )"),1.799E10) -> 17990000000 | E30: =IFERROR(__xludf.DUMMYFUNCTION("IFERROR( LET( x, UPPER(SUBSTITUTE(TRIM(Data!D95),CHAR(160),"""")), base, VALUE(SUBSTITUTE(REGEXEXTRACT(x,""[0-9.,]+""),"","","""")), mult, IF(REGEXMATCH(x,""B""),1000000000, IF(REGEXMATCH(x,""M""),1000000, 1)), base * mult ), 0 )"),1.827E10) -> 18270000000 | F30: =IFERROR(__xludf.DUMMYFUNCTION("IFERROR( LET( x, UPPER(SUBSTITUTE(TRIM(Data!E95),CHAR(160),"""")), base, VALUE(SUBSTITUTE(REGEXEXTRACT(x,""[0-9.,]+""),"","","""")), mult, IF(REGEXMATCH(x,""B""),1000000000, IF(REGEXMATCH(x,""M""),1000000, 1)), base * mult ), 0 )"),1.916E10) -> 19160000000 | G30: =IFERROR(__xludf.DUMMYFUNCTION("IFERROR( LET( x, UPPER(SUBSTITUTE(TRIM(Data!F95),CHAR(160),"""")), base, VALUE(SUBSTITUTE(REGEXEXTRACT(x,""[0-9.,]+""),"","","""")), mult, IF(REGEXMATCH(x,""B""),1000000000, IF(REGEXMATCH(x,""M""),1000000, 1)), base * mult ), 0 )"),2.191E10) -> 21910000000 | H30: =AVERAGE(C30:G30) -> 19104000000 | I30: =AVERAGE(D30:H30) -> 19286800000 | J30: =AVERAGE(E30:I30) -> 19546160000 | K30: =AVERAGE(F30:J30) -> 19801392000 | L30: =AVERAGE(G30:K30) -> 19929670400
B31: Net Property, Plant & Equipment | C31: =IFERROR(__xludf.DUMMYFUNCTION("IFERROR( LET( x, UPPER(SUBSTITUTE(TRIM(Data!B89),CHAR(160),"""")), base, VALUE(SUBSTITUTE(REGEXEXTRACT(x,""[0-9.,]+""),"","","""")), mult, IF(REGEXMATCH(x,""B""),1000000000, IF(REGEXMATCH(x,""M""),1000000, 1)), base * mult ), 0 )"),2.087E10) -> 20870000000 | D31: =IFERROR(__xludf.DUMMYFUNCTION("IFERROR( LET( x, UPPER(SUBSTITUTE(TRIM(Data!C89),CHAR(160),"""")), base, VALUE(SUBSTITUTE(REGEXEXTRACT(x,""[0-9.,]+""),"","","""")), mult, IF(REGEXMATCH(x,""B""),1000000000, IF(REGEXMATCH(x,""M""),1000000, 1)), base * mult ), 0 )"),2.277E10) -> 22770000000 | E31: =IFERROR(__xludf.DUMMYFUNCTION("IFERROR( LET( x, UPPER(SUBSTITUTE(TRIM(Data!D89),CHAR(160),"""")), base, VALUE(SUBSTITUTE(REGEXEXTRACT(x,""[0-9.,]+""),"","","""")), mult, IF(REGEXMATCH(x,""B""),1000000000, IF(REGEXMATCH(x,""M""),1000000, 1)), base * mult ), 0 )"),2.449E10) -> 24490000000 | F31: =IFERROR(__xludf.DUMMYFUNCTION("IFERROR( LET( x, UPPER(SUBSTITUTE(TRIM(Data!E89),CHAR(160),"""")), base, VALUE(SUBSTITUTE(REGEXEXTRACT(x,""[0-9.,]+""),"","","""")), mult, IF(REGEXMATCH(x,""B""),1000000000, IF(REGEXMATCH(x,""M""),1000000, 1)), base * mult ), 0 )"),2.515E10) -> 25150000000 | G31: =IFERROR(__xludf.DUMMYFUNCTION("IFERROR( LET( x, UPPER(SUBSTITUTE(TRIM(Data!F89),CHAR(160),"""")), base, VALUE(SUBSTITUTE(REGEXEXTRACT(x,""[0-9.,]+""),"","","""")), mult, IF(REGEXMATCH(x,""B""),1000000000, IF(REGEXMATCH(x,""M""),1000000, 1)), base * mult ), 0 )"),2.682E10) -> 26820000000 | H31: =AVERAGE(C31:G31) -> 24020000000 | I31: =AVERAGE(D31:H31) -> 24650000000 | J31: =AVERAGE(E31:I31) -> 25026000000 | K31: =AVERAGE(F31:J31) -> 25133200000 | L31: =AVERAGE(G31:K31) -> 25129840000
B34: Intangible Assets | C34: =IFERROR(__xludf.DUMMYFUNCTION("IFERROR( LET( x, UPPER(SUBSTITUTE(TRIM(Data!B99),CHAR(160),"""")), base, VALUE(SUBSTITUTE(REGEXEXTRACT(x,""[0-9.,]+""),"","","""")), mult, IF(REGEXMATCH(x,""B""),1000000000, IF(REGEXMATCH(x,""M""),1000000, 1)), base * mult ), )"),4.42E10) -> 44200000000 | D34: =IFERROR(__xludf.DUMMYFUNCTION("IFERROR( LET( x, UPPER(SUBSTITUTE(TRIM(Data!C99),CHAR(160),"""")), base, VALUE(SUBSTITUTE(REGEXEXTRACT(x,""[0-9.,]+""),"","","""")), mult, IF(REGEXMATCH(x,""B""),1000000000, IF(REGEXMATCH(x,""M""),1000000, 1)), base * mult ), )"),4.147E10) -> 41470000000 | E34: =IFERROR(__xludf.DUMMYFUNCTION("IFERROR( LET( x, UPPER(SUBSTITUTE(TRIM(Data!D99),CHAR(160),"""")), base, VALUE(SUBSTITUTE(REGEXEXTRACT(x,""[0-9.,]+""),"","","""")), mult, IF(REGEXMATCH(x,""B""),1000000000, IF(REGEXMATCH(x,""M""),1000000, 1)), base * mult ), )"),3.921E10) -> 39210000000 | F34: =IFERROR(__xludf.DUMMYFUNCTION("IFERROR( LET( x, UPPER(SUBSTITUTE(TRIM(Data!E99),CHAR(160),"""")), base, VALUE(SUBSTITUTE(REGEXEXTRACT(x,""[0-9.,]+""),"","","""")), mult, IF(REGEXMATCH(x,""B""),1000000000, IF(REGEXMATCH(x,""M""),1000000, 1)), base * mult ), )"),3.804E10) -> 38040000000 | G34: =IFERROR(__xludf.DUMMYFUNCTION("IFERROR( LET( x, UPPER(SUBSTITUTE(TRIM(Data!B99),CHAR(160),"""")), base, VALUE(SUBSTITUTE(REGEXEXTRACT(x,""[0-9.,]+""),"","","""")), mult, IF(REGEXMATCH(x,""B""),1000000000, IF(REGEXMATCH(x,""M""),1000000, 1)), base * mult ), 0 )"),4.42E10) -> 44200000000 | H34: =FORECAST(H3,$C$34:G34,$C$3:G3) -> 40395000000 | I34: =FORECAST(I3,$C$34:H34,$C$3:H3) -> 40052000000 | J34: =FORECAST(J3,$C$34:I34,$C$3:I3) -> 39709000000 | K34: =FORECAST(K3,$C$34:J34,$C$3:J3) -> 39366000000 | L34: =FORECAST(L3,$C$34:K34,$C$3:K3) -> 39023000000
B35: Other Assets | C35: =IFERROR(__xludf.DUMMYFUNCTION("IFERROR( LET( x, UPPER(SUBSTITUTE(TRIM(Data!B102),CHAR(160),"""")), base, VALUE(SUBSTITUTE(REGEXEXTRACT(x,""[0-9.,]+""),"","","""")), mult, IF(REGEXMATCH(x,""B""),1000000000, IF(REGEXMATCH(x,""M""),1000000, 1)), base * mult ), 0 )"),9.29E9) -> 9290000000 | D35: =IFERROR(__xludf.DUMMYFUNCTION("IFERROR( LET( x, UPPER(SUBSTITUTE(TRIM(Data!C102),CHAR(160),"""")), base, VALUE(SUBSTITUTE(REGEXEXTRACT(x,""[0-9.,]+""),"","","""")), mult, IF(REGEXMATCH(x,""B""),1000000000, IF(REGEXMATCH(x,""M""),1000000, 1)), base * mult ), 0 )"),7.24E9) -> 7240000000 | E35: =IFERROR(__xludf.DUMMYFUNCTION("IFERROR( LET( x, UPPER(SUBSTITUTE(TRIM(Data!D102),CHAR(160),"""")), base, VALUE(SUBSTITUTE(REGEXEXTRACT(x,""[0-9.,]+""),"","","""")), mult, IF(REGEXMATCH(x,""B""),1000000000, IF(REGEXMATCH(x,""M""),1000000, 1)), base * mult ), 0 )"),9.23E9) -> 9230000000 | F35: =IFERROR(__xludf.DUMMYFUNCTION("IFERROR( LET( x, UPPER(SUBSTITUTE(TRIM(Data!E102),CHAR(160),"""")), base, VALUE(SUBSTITUTE(REGEXEXTRACT(x,""[0-9.,]+""),"","","""")), mult, IF(REGEXMATCH(x,""B""),1000000000, IF(REGEXMATCH(x,""M""),1000000, 1)), base * mult ), 0 )"),1.346E10) -> 13460000000 | G35: =IFERROR(__xludf.DUMMYFUNCTION("IFERROR( LET( x, UPPER(SUBSTITUTE(TRIM(Data!F102),CHAR(160),"""")), base, VALUE(SUBSTITUTE(REGEXEXTRACT(x,""[0-9.,]+""),"","","""")), mult, IF(REGEXMATCH(x,""B""),1000000000, IF(REGEXMATCH(x,""M""),1000000, 1)), base * mult ), 0 )"),1.6030000000000002E10) -> 16030000000 | H35: =FORECAST(H3,$C$35:G35,$C$3:G3) -> 16960000000 | I35: =FORECAST(I3,$C$35:H35,$C$3:H3) -> 18930000000 | J35: =FORECAST(J3,$C$35:I35,$C$3:I3) -> 20900000000 | K35: =FORECAST(K3,$C$35:J35,$C$3:J3) -> 22870000000 | L35: =FORECAST(L3,$C$35:K35,$C$3:K3) -> 24840000000
B36: Total Assets | C36: =IFERROR(__xludf.DUMMYFUNCTION("regexreplace(Data!B103,""B"","""")*1000000000"),1.0569E11) -> 105690000000 | D36: =IFERROR(__xludf.DUMMYFUNCTION("regexreplace(Data!C103,""B"","""")*1000000000"),1.0916E11) -> 109160000000 | E36: =IFERROR(__xludf.DUMMYFUNCTION("regexreplace(Data!D103,""B"","""")*1000000000"),1.0668E11) -> 106680000000 | F36: =IFERROR(__xludf.DUMMYFUNCTION("regexreplace(Data!E103,""B"","""")*1000000000"),1.1711E11) -> 117110000000 | G36: =IFERROR(__xludf.DUMMYFUNCTION("regexreplace(Data!F103,""B"","""")*1000000000"),1.3687E11) -> 136870000000 | H36: =G36*(1+H37) -> 146008069762 | I36: =H36*(1+I37) -> 155756239027 | J36: =I36*(1+J37) -> 166155240840 | K36: =J36*(1+K37) -> 177248527770 | L36: =K36*(1+L37) -> 189082453480
B37: Total Assets Growth | C37: - | D37: =Data!C104 -> 0.0328 | E37: =Data!D104 -> -0.0228 | F37: =Data!E104 -> 0.0978 | G37: =Data!F104 -> 0.1687 | H37: =(G36/C36)^(1/4)-1 -> 0.066764592 | I37: =H37 -> 0.066764592 | J37: =I37 -> 0.066764592 | K37: =J37 -> 0.066764592 | L37: =K37 -> 0.066764592
B40: Short Term Debt | C40: =IFERROR(__xludf.DUMMYFUNCTION("IFERROR( LET( x, UPPER(SUBSTITUTE(TRIM(Data!B334),CHAR(160),"""")), base, VALUE(SUBSTITUTE(REGEXEXTRACT(x,""[0-9.,]+""),"","","""")), mult, IF(REGEXMATCH(x,""B""),1000000000, IF(REGEXMATCH(x,""M""),1000000, 1)), base * mult ), 0 )"),2.72E9) -> 2720000000 | D40: =IFERROR(__xludf.DUMMYFUNCTION("IFERROR( LET( x, UPPER(SUBSTITUTE(TRIM(Data!C334),CHAR(160),"""")), base, VALUE(SUBSTITUTE(REGEXEXTRACT(x,""[0-9.,]+""),"","","""")), mult, IF(REGEXMATCH(x,""B""),1000000000, IF(REGEXMATCH(x,""M""),1000000, 1)), base * mult ), 0 )"),2.23E9) -> 2230000000 | E40: =IFERROR(__xludf.DUMMYFUNCTION("IFERROR( LET( x, UPPER(SUBSTITUTE(TRIM(Data!D334),CHAR(160),"""")), base, VALUE(SUBSTITUTE(REGEXEXTRACT(x,""[0-9.,]+""),"","","""")), mult, IF(REGEXMATCH(x,""B""),1000000000, IF(REGEXMATCH(x,""M""),1000000, 1)), base * mult ), 0 )"),1.66E9) -> 1660000000 | F40: =IFERROR(__xludf.DUMMYFUNCTION("IFERROR( LET( x, UPPER(SUBSTITUTE(TRIM(Data!E334),CHAR(160),"""")), base, VALUE(SUBSTITUTE(REGEXEXTRACT(x,""[0-9.,]+""),"","","""")), mult, IF(REGEXMATCH(x,""B""),1000000000, IF(REGEXMATCH(x,""M""),1000000, 1)), base * mult ), 0 )"),2.93E9) -> 2930000000 | G40: =IFERROR(__xludf.DUMMYFUNCTION("IFERROR( LET( x, UPPER(SUBSTITUTE(TRIM(Data!F334),CHAR(160),"""")), base, VALUE(SUBSTITUTE(REGEXEXTRACT(x,""[0-9.,]+""),"","","""")), mult, IF(REGEXMATCH(x,""B""),1000000000, IF(REGEXMATCH(x,""M""),1000000, 1)), base * mult ), 0 )"),2.88E9) -> 2880000000 | H40: =FORECAST(H3,$C$40:G40,$C$3:G3) -> 2790000000 | I40: =FORECAST(I3,$C$40:H40,$C$3:H3) -> 2892000000 | J40: =FORECAST(J3,$C$40:I40,$C$3:I3) -> 2994000000 | K40: =FORECAST(K3,$C$40:J40,$C$3:J3) -> 3096000000 | L40: =FORECAST(L3,$C$40:K40,$C$3:K3) -> 3198000000
B41: Current Portion of Long Term Debt | C41: =IFERROR(__xludf.DUMMYFUNCTION("IFERROR( LET( x, UPPER(SUBSTITUTE(TRIM(Data!B335),CHAR(160),"""")), base, VALUE(SUBSTITUTE(REGEXEXTRACT(x,""[0-9.,]+""),"","","""")), mult, IF(REGEXMATCH(x,""B""),1000000000, IF(REGEXMATCH(x,""M""),1000000, 1)), base * mult ), 0 )"),0.0) -> 0 | D41: =IFERROR(__xludf.DUMMYFUNCTION("IFERROR( LET( x, UPPER(SUBSTITUTE(TRIM(Data!C335),CHAR(160),"""")), base, VALUE(SUBSTITUTE(REGEXEXTRACT(x,""[0-9.,]+""),"","","""")), mult, IF(REGEXMATCH(x,""B""),1000000000, IF(REGEXMATCH(x,""M""),1000000, 1)), base * mult ), 0 )"),0.0) -> 0 | E41: =IFERROR(__xludf.DUMMYFUNCTION("IFERROR( LET( x, UPPER(SUBSTITUTE(TRIM(Data!D335),CHAR(160),"""")), base, VALUE(SUBSTITUTE(REGEXEXTRACT(x,""[0-9.,]+""),"","","""")), mult, IF(REGEXMATCH(x,""B""),1000000000, IF(REGEXMATCH(x,""M""),1000000, 1)), base * mult ), 0 )"),0.0) -> 0 | F41: =IFERROR(__xludf.DUMMYFUNCTION("IFERROR( LET( x, UPPER(SUBSTITUTE(TRIM(Data!E335),CHAR(160),"""")), base, VALUE(SUBSTITUTE(REGEXEXTRACT(x,""[0-9.,]+""),"","","""")), mult, IF(REGEXMATCH(x,""B""),1000000000, IF(REGEXMATCH(x,""M""),1000000, 1)), base * mult ), 0 )"),0.0) -> 0 | G41: =IFERROR(__xludf.DUMMYFUNCTION("IFERROR( LET( x, UPPER(SUBSTITUTE(TRIM(Data!F335),CHAR(160),"""")), base, VALUE(SUBSTITUTE(REGEXEXTRACT(x,""[0-9.,]+""),"","","""")), mult, IF(REGEXMATCH(x,""B""),1000000000, IF(REGEXMATCH(x,""M""),1000000, 1)), base * mult ), 0 )"),0.0) -> 0 | H41: =AVERAGE(C41:G41) -> 0 | I41: =AVERAGE(D41:H41) -> 0 | J41: =AVERAGE(E41:I41) -> 0 | K41: =AVERAGE(F41:J41) -> 0 | L41: =AVERAGE(G41:K41) -> 0
B42: ST Debt & Current Portion LT Debt | C42: =IFERROR(__xludf.DUMMYFUNCTION("IFERROR( LET( x, UPPER(SUBSTITUTE(TRIM(Data!B333),CHAR(160),"""")), base, VALUE(SUBSTITUTE(REGEXEXTRACT(x,""[0-9.,]+""),"","","""")), mult, IF(REGEXMATCH(x,""B""),1000000000, IF(REGEXMATCH(x,""M""),1000000, 1)), base * mult ), 0 )"),2.72E9) -> 2720000000 | D42: =IFERROR(__xludf.DUMMYFUNCTION("IFERROR( LET( x, UPPER(SUBSTITUTE(TRIM(Data!C333),CHAR(160),"""")), base, VALUE(SUBSTITUTE(REGEXEXTRACT(x,""[0-9.,]+""),"","","""")), mult, IF(REGEXMATCH(x,""B""),1000000000, IF(REGEXMATCH(x,""M""),1000000, 1)), base * mult ), 0 )"),2.23E9) -> 2230000000 | E42: =IFERROR(__xludf.DUMMYFUNCTION("IFERROR( LET( x, UPPER(SUBSTITUTE(TRIM(Data!D333),CHAR(160),"""")), base, VALUE(SUBSTITUTE(REGEXEXTRACT(x,""[0-9.,]+""),"","","""")), mult, IF(REGEXMATCH(x,""B""),1000000000, IF(REGEXMATCH(x,""M""),1000000, 1)), base * mult ), 0 )"),1.66E9) -> 1660000000 | F42: =IFERROR(__xludf.DUMMYFUNCTION("IFERROR( LET( x, UPPER(SUBSTITUTE(TRIM(Data!E333),CHAR(160),"""")), base, VALUE(SUBSTITUTE(REGEXEXTRACT(x,""[0-9.,]+""),"","","""")), mult, IF(REGEXMATCH(x,""B""),1000000000, IF(REGEXMATCH(x,""M""),1000000, 1)), base * mult ), 0 )"),2.93E9) -> 2930000000 | G42: =IFERROR(__xludf.DUMMYFUNCTION("IFERROR( LET( x, UPPER(SUBSTITUTE(TRIM(Data!F333),CHAR(160),"""")), base, VALUE(SUBSTITUTE(REGEXEXTRACT(x,""[0-9.,]+""),"","","""")), mult, IF(REGEXMATCH(x,""B""),1000000000, IF(REGEXMATCH(x,""M""),1000000, 1)), base * mult ), 0 )"),2.88E9) -> 2880000000 | H42: =FORECAST(H3,$C$42:G42,$C$3:G3) -> 2790000000 | I42: =FORECAST(I3,$C$42:H42,$C$3:H3) -> 2892000000 | J42: =FORECAST(J3,$C$42:I42,$C$3:I3) -> 2994000000 | K42: =FORECAST(K3,$C$42:J42,$C$3:J3) -> 3096000000 | L42: =FORECAST(L3,$C$42:K42,$C$3:K3) -> 3198000000

Sheet Cash Flow
B2: Balance Sheet | C2: FY | H2: Future FY
C3: 2020 | D3: 2021 | E3: 2022 | F3: 2023 | G3: 2024 | H3: 2025 | I3: 2026 | J3: 2027 | K3: 2028 | L3: 2029
B6: Net Income before Extraordinaries | C6: =IFERROR(__xludf.DUMMYFUNCTION("IFERROR( LET( x, UPPER(SUBSTITUTE(TRIM(Data!B112),CHAR(160),"""")), base, VALUE(SUBSTITUTE(REGEXEXTRACT(x,""[0-9.,]+""),"","","""")), mult, IF(REGEXMATCH(x,""B""),1000000000, IF(REGEXMATCH(x,""M""),1000000, 1)), base * mult ), 0 ) "),1.236E10) -> 12360000000 | D6: =IFERROR(__xludf.DUMMYFUNCTION("IFERROR( LET( x, UPPER(SUBSTITUTE(TRIM(Data!C112),CHAR(160),"""")), base, VALUE(SUBSTITUTE(REGEXEXTRACT(x,""[0-9.,]+""),"","","""")), mult, IF(REGEXMATCH(x,""B""),1000000000, IF(REGEXMATCH(x,""M""),1000000, 1)), base * mult ), )"),1.453E10) -> 14530000000 | E6: =IFERROR(__xludf.DUMMYFUNCTION("IFERROR( LET( x, UPPER(SUBSTITUTE(TRIM(Data!D112),CHAR(160),"""")), base, VALUE(SUBSTITUTE(REGEXEXTRACT(x,""[0-9.,]+""),"","","""")), mult, IF(REGEXMATCH(x,""B""),1000000000, IF(REGEXMATCH(x,""M""),1000000, 1)), base * mult ), )"),3.77E8) -> 377000000 | F6: =IFERROR(__xludf.DUMMYFUNCTION("IFERROR( LET( x, UPPER(SUBSTITUTE(TRIM(Data!E112),CHAR(160),"""")), base, VALUE(SUBSTITUTE(REGEXEXTRACT(x,""[0-9.,]+""),"","","""")), mult, IF(REGEXMATCH(x,""B""),1000000000, IF(REGEXMATCH(x,""M""),1000000, 1)), base * mult ), )"),1.7129999999999998E10) -> 17130000000 | G6: =IFERROR(__xludf.DUMMYFUNCTION("IFERROR( LET( x, UPPER(SUBSTITUTE(TRIM(Data!F112),CHAR(160),"""")), base, VALUE(SUBSTITUTE(REGEXEXTRACT(x,""[0-9.,]+""),"","","""")), mult, IF(REGEXMATCH(x,""B""),1000000000, IF(REGEXMATCH(x,""M""),1000000, 1)), base * mult ), )"),1.826E10) -> 18260000000 | H6: =FORECAST(H3,$C$6:G6,$C$3:G3) -> 16851400000 | I6: =FORECAST(I3,$C$6:H6,$C$3:H3) -> 18291400000 | J6: =FORECAST(J3,$C$6:I6,$C$3:I3) -> 19731400000 | K6: =FORECAST(K3,$C$6:J6,$C$3:J3) -> 21171400000 | L6: =FORECAST(L3,$C$6:K6,$C$3:K3) -> 22611400000
B7: Net Income Growth | C7: =Data!B113 -> - | D7: =Data!C113 -> 0.1754 | E7: =Data!D113 -> -0.974 | F7: =Data!E113 -> 44.4456 | G7: =Data!F113 -> 0.066 | H7: =H6/G6-1 -> -0.077141292 | I7: =I6/H6-1 -> 0.085452841 | J7: =J6/I6-1 -> 0.078725521 | K7: =K6/J6-1 -> 0.072980123 | L7: =L6/K6-1 -> 0.068016286
B10: Depreciation, Depletion & Amortization | C10: =IFERROR(__xludf.DUMMYFUNCTION("IFERROR( LET( x, UPPER(SUBSTITUTE(TRIM(Data!B114),CHAR(160),"""")), base, VALUE(SUBSTITUTE(REGEXEXTRACT(x,""[0-9.,]+""),"","","""")), mult, IF(REGEXMATCH(x,""B""),1000000000, IF(REGEXMATCH(x,""M""),1000000, 1)), base * mult ), 0 ) "),3.21E9) -> 3210000000 | D10: =IFERROR(__xludf.DUMMYFUNCTION("IFERROR( LET( x, UPPER(SUBSTITUTE(TRIM(Data!C114),CHAR(160),"""")), base, VALUE(SUBSTITUTE(REGEXEXTRACT(x,""[0-9.,]+""),"","","""")), mult, IF(REGEXMATCH(x,""B""),1000000000, IF(REGEXMATCH(x,""M""),1000000, 1)), base * mult ), 0 ) "),3.91E9) -> 3910000000 | E10: =IFERROR(__xludf.DUMMYFUNCTION("IFERROR( LET( x, UPPER(SUBSTITUTE(TRIM(Data!D114),CHAR(160),"""")), base, VALUE(SUBSTITUTE(REGEXEXTRACT(x,""[0-9.,]+""),"","","""")), mult, IF(REGEXMATCH(x,""B""),1000000000, IF(REGEXMATCH(x,""M""),1000000, 1)), base * mult ), 0 ) "),3.87E9) -> 3870000000 | F10: =IFERROR(__xludf.DUMMYFUNCTION("IFERROR( LET( x, UPPER(SUBSTITUTE(TRIM(Data!E114),CHAR(160),"""")), base, VALUE(SUBSTITUTE(REGEXEXTRACT(x,""[0-9.,]+""),"","","""")), mult, IF(REGEXMATCH(x,""B""),1000000000, IF(REGEXMATCH(x,""M""),1000000, 1)), base * mult ), 0 ) "),4.5E9) -> 4500000000 | G10: =IFERROR(__xludf.DUMMYFUNCTION("IFERROR( LET( x, UPPER(SUBSTITUTE(TRIM(Data!F114),CHAR(160),"""")), base, VALUE(SUBSTITUTE(REGEXEXTRACT(x,""[0-9.,]+""),"","","""")), mult, IF(REGEXMATCH(x,""B""),1000000000, IF(REGEXMATCH(x,""M""),1000000, 1)), base * mult ), 0 ) "),5.84E9) -> 5840000000 | H10: =FORECAST(H3,$C$10:G10,$C$3:G3) -> 6021000000 | I10: =FORECAST(I3,$C$10:H10,$C$3:H3) -> 6606000000 | J10: =FORECAST(J3,$C$10:I10,$C$3:I3) -> 7191000000 | K10: =FORECAST(K3,$C$10:J10,$C$3:J3) -> 7776000000 | L10: =FORECAST(L3,$C$10:K10,$C$3:K3) -> 8361000000
B13: Net Operating Cash Flow | C13: =IFERROR(__xludf.DUMMYFUNCTION("IFERROR( LET( x, UPPER(SUBSTITUTE(TRIM(Data!B127),CHAR(160),"""")), base, VALUE(SUBSTITUTE(REGEXEXTRACT(x,""[0-9.,]+""),"","","""")), mult, IF(REGEXMATCH(x,""B""),1000000000, IF(REGEXMATCH(x,""M""),1000000, 1)), base * mult ), 0 ) "),1.411E10) -> 14110000000 | D13: =IFERROR(__xludf.DUMMYFUNCTION("IFERROR( LET( x, UPPER(SUBSTITUTE(TRIM(Data!C127),CHAR(160),"""")), base, VALUE(SUBSTITUTE(REGEXEXTRACT(x,""[0-9.,]+""),"","","""")), mult, IF(REGEXMATCH(x,""B""),1000000000, IF(REGEXMATCH(x,""M""),1000000, 1)), base * mult ), 0 ) "),1.91E10) -> 19100000000 | E13: =IFERROR(__xludf.DUMMYFUNCTION("IFERROR( LET( x, UPPER(SUBSTITUTE(TRIM(Data!D127),CHAR(160),"""")), base, VALUE(SUBSTITUTE(REGEXEXTRACT(x,""[0-9.,]+""),"","","""")), mult, IF(REGEXMATCH(x,""B""),1000000000, IF(REGEXMATCH(x,""M""),1000000, 1)), base * mult ), 0 ) "),1.301E10) -> 13010000000 | F13: =IFERROR(__xludf.DUMMYFUNCTION("IFERROR( LET( x, UPPER(SUBSTITUTE(TRIM(Data!E127),CHAR(160),"""")), base, VALUE(SUBSTITUTE(REGEXEXTRACT(x,""[0-9.,]+""),"","","""")), mult, IF(REGEXMATCH(x,""B""),1000000000, IF(REGEXMATCH(x,""M""),1000000, 1)), base * mult ), 0 ) "),2.147E10) -> 21470000000 | G13: =IFERROR(__xludf.DUMMYFUNCTION("IFERROR( LET( x, UPPER(SUBSTITUTE(TRIM(Data!F127),CHAR(160),"""")), base, VALUE(SUBSTITUTE(REGEXEXTRACT(x,""[0-9.,]+""),"","","""")), mult, IF(REGEXMATCH(x,""B""),1000000000, IF(REGEXMATCH(x,""M""),1000000, 1)), base * mult ), 0 ) "),1.6469999999999998E10) -> 16470000000 | H13: =FORECAST(H3,$C$13:G13,$C$3:G3) -> 18959000000 | I13: =FORECAST(I3,$C$13:H13,$C$3:H3) -> 19668000000 | J13: =FORECAST(J3,$C$13:I13,$C$3:I3) -> 20377000000 | K13: =FORECAST(K3,$C$13:J13,$C$3:J3) -> 21086000000 | L13: =FORECAST(L3,$C$13:K13,$C$3:K3) -> 21795000000
B14: Net Operating Cash Flow Growth | C14: =Data!B128 -> - | D14: =Data!C128 -> 0.3534 | E14: =Data!D128 -> -0.3189 | F14: =Data!E128 -> 0.6506 | G14: =Data!F128 -> -0.2327 | H14: =H13/G13-1 -> 0.15112325 | I14: =I13/H13-1 -> 0.037396487 | J14: =J13/I13-1 -> 0.036048403 | K14: =K13/J13-1 -> 0.034794131 | L14: =L13/K13-1 -> 0.033624206
B17: Net Change in Cash | C17: =IFERROR(__xludf.DUMMYFUNCTION("IFERROR( LET( x, UPPER(SUBSTITUTE(TRIM(Data!B153),CHAR(160),"""")), base, VALUE(SUBSTITUTE(REGEXEXTRACT(x,""[0-9.,]+""),"","","""")), mult, IF(REGEXMATCH(x,""B""),1000000000, IF(REGEXMATCH(x,""M""),1000000, 1)), base * mult ), 0 ) "),1.4E7) -> 14000000 | D17: =IFERROR(__xludf.DUMMYFUNCTION("IFERROR( LET( x, UPPER(SUBSTITUTE(TRIM(Data!C153),CHAR(160),"""")), base, VALUE(SUBSTITUTE(REGEXEXTRACT(x,""[0-9.,]+""),"","","""")), mult, IF(REGEXMATCH(x,""B""),1000000000, IF(REGEXMATCH(x,""M""),1000000, 1)), base * mult ), 0 ) "),4.61E9) -> 4610000000 | E17: =IFERROR(__xludf.DUMMYFUNCTION("IFERROR( LET( x, UPPER(SUBSTITUTE(TRIM(Data!D153),CHAR(160),"""")), base, VALUE(SUBSTITUTE(REGEXEXTRACT(x,""[0-9.,]+""),"","","""")), mult, IF(REGEXMATCH(x,""B""),1000000000, IF(REGEXMATCH(x,""M""),1000000, 1)), base * mult ), 0 ) "),5.86E9) -> 5860000000 | F17: =IFERROR(__xludf.DUMMYFUNCTION("IFERROR( LET( x, UPPER(SUBSTITUTE(TRIM(Data!E153),CHAR(160),"""")), base, VALUE(SUBSTITUTE(REGEXEXTRACT(x,""[0-9.,]+""),"","","""")), mult, IF(REGEXMATCH(x,""B""),1000000000, IF(REGEXMATCH(x,""M""),1000000, 1)), base * mult ), 0 ) "),6.41E9) -> 6410000000 | G17: =IFERROR(__xludf.DUMMYFUNCTION("IFERROR( LET( x, UPPER(SUBSTITUTE(TRIM(Data!F153),CHAR(160),"""")), base, VALUE(SUBSTITUTE(REGEXEXTRACT(x,""[0-9.,]+""),"","","""")), mult, IF(REGEXMATCH(x,""B""),1000000000, IF(REGEXMATCH(x,""M""),1000000, 1)), base * mult ), 0 ) "),1.37E9) -> 1370000000 | H17: =AVERAGEIF(C17:G17,">0.5") -> 3652800000 | I17: =AVERAGEIF(D17:H17,">0.5") -> 4380560000 | J17: =AVERAGEIF(E17:I17,">0.5") -> 4334672000 | K17: =AVERAGEIF(F17:J17,">0.5") -> 4029606400 | L17: =AVERAGEIF(G17:K17,">0.5") -> 3553527680
B18: Free Cash Flow | C18: =IFERROR(__xludf.DUMMYFUNCTION("IFERROR( LET( x, UPPER(SUBSTITUTE(TRIM(Data!B154),CHAR(160),"""")), base, VALUE(SUBSTITUTE(REGEXEXTRACT(x,""[0-9.,]+""),"","","""")), mult, IF(REGEXMATCH(x,""B""),1000000000, IF(REGEXMATCH(x,""M""),1000000, 1)), base * mult ), 0 ) "),9.66E9) -> 9660000000 | D18: =IFERROR(__xludf.DUMMYFUNCTION("IFERROR( LET( x, UPPER(SUBSTITUTE(TRIM(Data!C154),CHAR(160),"""")), base, VALUE(SUBSTITUTE(REGEXEXTRACT(x,""[0-9.,]+""),"","","""")), mult, IF(REGEXMATCH(x,""B""),1000000000, IF(REGEXMATCH(x,""M""),1000000, 1)), base * mult ), 0 ) "),1.471E10) -> 14710000000 | E18: =IFERROR(__xludf.DUMMYFUNCTION("IFERROR( LET( x, UPPER(SUBSTITUTE(TRIM(Data!D154),CHAR(160),"""")), base, VALUE(SUBSTITUTE(REGEXEXTRACT(x,""[0-9.,]+""),"","","""")), mult, IF(REGEXMATCH(x,""B""),1000000000, IF(REGEXMATCH(x,""M""),1000000, 1)), base * mult ), 0 ) "),9.14E9) -> 9140000000 | F18: =IFERROR(__xludf.DUMMYFUNCTION("IFERROR( LET( x, UPPER(SUBSTITUTE(TRIM(Data!E154),CHAR(160),"""")), base, VALUE(SUBSTITUTE(REGEXEXTRACT(x,""[0-9.,]+""),"","","""")), mult, IF(REGEXMATCH(x,""B""),1000000000, IF(REGEXMATCH(x,""M""),1000000, 1)), base * mult ), 0 ) "),1.81E10) -> 18100000000 | G18: =IFERROR(__xludf.DUMMYFUNCTION("IFERROR( LET( x, UPPER(SUBSTITUTE(TRIM(Data!F154),CHAR(160),"""")), base, VALUE(SUBSTITUTE(REGEXEXTRACT(x,""[0-9.,]+""),"","","""")), mult, IF(REGEXMATCH(x,""B""),1000000000, IF(REGEXMATCH(x,""M""),1000000, 1)), base * mult ), 0 ) "),1.236E10) -> 12360000000 | H18: =G18*(1+H19) -> 13145551376 | I18: =H18*(1+I19) -> 13586662664 | J18: =I18*(1+J19) -> 13634975975 | K18: =J18*(1+K19) -> 13274411805 | L18: =K18*(1+L19) -> 12525150063
B19: Free Cash Flow Growth | C19: =Data!B155 -> - | D19: =Data!C155 -> 0.5223 | E19: =Data!D155 -> -0.3783 | F19: =Data!E155 -> 0.9792 | G19: =Data!F155 -> -0.317 | H19: =(G18/C18)^(1/4)-1 -> 0.063555937 | I19: =H19-3% -> 0.033555937 | J19: =I19-3% -> 0.0035559366 | K19: =J19-3% -> -0.026444063 | L19: =K19-3% -> -0.056444063

Sheet DCF
G2: TradingView Revenue Estimates
B4: Discounted Cash Flow | C4: FY | H4: Future FY
C5: 2020 | D5: 2021 | E5: 2022 | F5: 2023 | G5: 2024 | H5: 2025 | I5: 2026 | J5: 2027 | K5: 2028
B8: Revenue | C8: ='Income Statement'!C15 -> 48910000000 | D8: ='Income Statement'!D15 -> 58470000000 | E8: ='Income Statement'!E15 -> 59870000000 | F8: ='Income Statement'!F15 -> 63970000000 | G8: ='Income Statement'!G15 -> 64930000000 | H8: 66680000000 | I8: 70170000000 | J8: 74750000000 | K8: 74520000000
B9: % growth | C9: - | D9: =D8/C8-1 -> 0.19546105 | E9: =E8/D8-1 -> 0.023943903 | F9: =F8/E8-1 -> 0.06848171 | G9: =G8/F8-1 -> 0.015007035 | H9: =H8/G8-1 -> 0.026952102 | I9: =I8/H8-1 -> 0.052339532 | J9: =J8/I8-1 -> 0.065270058 | K9: =K8/J8-1 -> -0.0030769231
B12: EBIT | C12: =IFERROR(__xludf.DUMMYFUNCTION("IFERROR( LET( x, UPPER(SUBSTITUTE(TRIM(Data!B22),CHAR(160),"""")), neg, IF(LEFT(x,1)=""("", -1, 1), numtext, REGEXEXTRACT(x,""[0-9.,]+""), base, VALUE(SUBSTITUTE(numtext,"","","""")), mult, IF(REGEXMATCH(x,""B""),1000000000, IF(REGEX"&"MATCH(x,""M""),1000000, 1)), neg * base * mult ), 0 ) "),1.246E10) -> 12460000000 | D12: =IFERROR(__xludf.DUMMYFUNCTION("IFERROR( LET( x, UPPER(SUBSTITUTE(TRIM(Data!C22),CHAR(160),"""")), neg, IF(LEFT(x,1)=""("", -1, 1), numtext, REGEXEXTRACT(x,""[0-9.,]+""), base, VALUE(SUBSTITUTE(numtext,"","","""")), mult, IF(REGEXMATCH(x,""B""),1000000000, IF(REGEX"&"MATCH(x,""M""),1000000, 1)), neg * base * mult ), 0 ) "),1.723E10) -> 17230000000 | E12: =IFERROR(__xludf.DUMMYFUNCTION("IFERROR( LET( x, UPPER(SUBSTITUTE(TRIM(Data!D22),CHAR(160),"""")), neg, IF(LEFT(x,1)=""("", -1, 1), numtext, REGEXEXTRACT(x,""[0-9.,]+""), base, VALUE(SUBSTITUTE(numtext,"","","""")), mult, IF(REGEXMATCH(x,""B""),1000000000, IF(REGEX"&"MATCH(x,""M""),1000000, 1)), neg * base * mult ), 0 ) "),1.95E9) -> 1950000000 | F12: =IFERROR(__xludf.DUMMYFUNCTION("IFERROR( LET( x, UPPER(SUBSTITUTE(TRIM(Data!E22),CHAR(160),"""")), neg, IF(LEFT(x,1)=""("", -1, 1), numtext, REGEXEXTRACT(x,""[0-9.,]+""), base, VALUE(SUBSTITUTE(numtext,"","","""")), mult, IF(REGEXMATCH(x,""B""),1000000000, IF(REGEX"&"MATCH(x,""M""),1000000, 1)), neg * base * mult ), 0 ) "),1.947E10) -> 19470000000 | G12: =IFERROR(__xludf.DUMMYFUNCTION("IFERROR( LET( x, UPPER(SUBSTITUTE(TRIM(Data!F22),CHAR(160),"""")), neg, IF(LEFT(x,1)=""("", -1, 1), numtext, REGEXEXTRACT(x,""[0-9.,]+""), base, VALUE(SUBSTITUTE(numtext,"","","""")), mult, IF(REGEXMATCH(x,""B""),1000000000, IF(REGEX"&"MATCH(x,""M""),1000000, 1)), neg * base * mult ), 0 ) "),2.178E10) -> 21780000000 | H12: =H8*H13 -> 14944547271 | I12: =I8*I13 -> 15726737882 | J12: =J8*J13 -> 16753222983 | K12: =K8*K13 -> 16701674604
B13: % of sales | C13: =C12/C8 -> 0.25475363 | D13: =D12/D8 -> 0.29468103 | E13: =E12/E8 -> 0.03257057 | F13: =F12/F8 -> 0.30436142 | G13: =G12/G8 -> 0.33543816 | H13: =AVERAGEIF(E13:G13,">0.01") -> 0.22412338 | I13: =H13 -> 0.22412338 | J13: =I13 -> 0.22412338 | K13: =J13 -> 0.22412338
